[2022-12-12 12:42:51,016] {taskinstance.py:1159} INFO - Dependencies all met for <TaskInstance: prepare_data.create_table scheduled__2022-11-28T21:35:00+00:00 [queued]>
[2022-12-12 12:42:51,481] {taskinstance.py:1159} INFO - Dependencies all met for <TaskInstance: prepare_data.create_table scheduled__2022-11-28T21:35:00+00:00 [queued]>
[2022-12-12 12:42:51,481] {taskinstance.py:1356} INFO - 
--------------------------------------------------------------------------------
[2022-12-12 12:42:51,481] {taskinstance.py:1357} INFO - Starting attempt 1 of 1
[2022-12-12 12:42:51,481] {taskinstance.py:1358} INFO - 
--------------------------------------------------------------------------------
[2022-12-12 12:42:52,339] {taskinstance.py:1377} INFO - Executing <Task(PostgresOperator): create_table> on 2022-11-28 21:35:00+00:00
[2022-12-12 12:42:52,495] {standard_task_runner.py:52} INFO - Started process 974 to run task
[2022-12-12 12:42:52,721] {standard_task_runner.py:79} INFO - Running: ['airflow', 'tasks', 'run', 'prepare_data', 'create_table', 'scheduled__2022-11-28T21:35:00+00:00', '--job-id', '303', '--raw', '--subdir', 'DAGS_FOLDER/prepare_data.py', '--cfg-path', '/tmp/tmp99c8gcsz', '--error-file', '/tmp/tmp4ojy260k']
[2022-12-12 12:42:52,897] {standard_task_runner.py:80} INFO - Job 303: Subtask create_table
[2022-12-12 12:42:55,438] {task_command.py:369} INFO - Running <TaskInstance: prepare_data.create_table scheduled__2022-11-28T21:35:00+00:00 [running]> on host b778137d8ea6
[2022-12-12 12:42:59,112] {taskinstance.py:1571} INFO - Exporting the following env vars:
AIRFLOW_CTX_DAG_OWNER=airflow
AIRFLOW_CTX_DAG_ID=prepare_data
AIRFLOW_CTX_TASK_ID=create_table
AIRFLOW_CTX_EXECUTION_DATE=2022-11-28T21:35:00+00:00
AIRFLOW_CTX_TRY_NUMBER=1
AIRFLOW_CTX_DAG_RUN_ID=scheduled__2022-11-28T21:35:00+00:00
[2022-12-12 12:43:01,377] {taskinstance.py:1889} ERROR - Task failed with exception
Traceback (most recent call last):
  File "/home/airflow/.local/lib/python3.7/site-packages/airflow/providers/postgres/operators/postgres.py", line 92, in execute
    self.hook.run(self.sql, self.autocommit, parameters=self.parameters)
  File "/home/airflow/.local/lib/python3.7/site-packages/airflow/hooks/dbapi.py", line 181, in run
    with closing(self.get_conn()) as conn:
  File "/home/airflow/.local/lib/python3.7/site-packages/airflow/providers/postgres/hooks/postgres.py", line 86, in get_conn
    conn = deepcopy(self.connection or self.get_connection(conn_id))
  File "/home/airflow/.local/lib/python3.7/site-packages/airflow/hooks/base.py", line 67, in get_connection
    conn = Connection.get_connection_from_secrets(conn_id)
  File "/home/airflow/.local/lib/python3.7/site-packages/airflow/models/connection.py", line 430, in get_connection_from_secrets
    raise AirflowNotFoundException(f"The conn_id `{conn_id}` isn't defined")
airflow.exceptions.AirflowNotFoundException: The conn_id `postgres_default` isn't defined
[2022-12-12 12:43:01,473] {taskinstance.py:1400} INFO - Marking task as FAILED. dag_id=prepare_data, task_id=create_table, execution_date=20221128T213500, start_date=20221212T124251, end_date=20221212T124301
[2022-12-12 12:43:01,928] {standard_task_runner.py:97} ERROR - Failed to execute job 303 for task create_table (The conn_id `postgres_default` isn't defined; 974)
[2022-12-12 12:43:02,083] {local_task_job.py:156} INFO - Task exited with return code 1
[2022-12-12 12:43:03,408] {local_task_job.py:273} INFO - 0 downstream tasks scheduled from follow-on schedule check
