[2022-12-03 15:12:35,616] {taskinstance.py:1159} INFO - Dependencies all met for <TaskInstance: prepare_data.get_last_id scheduled__2022-11-28T20:02:00+00:00 [queued]>
[2022-12-03 15:12:36,218] {taskinstance.py:1159} INFO - Dependencies all met for <TaskInstance: prepare_data.get_last_id scheduled__2022-11-28T20:02:00+00:00 [queued]>
[2022-12-03 15:12:36,230] {taskinstance.py:1356} INFO - 
--------------------------------------------------------------------------------
[2022-12-03 15:12:36,231] {taskinstance.py:1357} INFO - Starting attempt 1 of 1
[2022-12-03 15:12:36,231] {taskinstance.py:1358} INFO - 
--------------------------------------------------------------------------------
[2022-12-03 15:12:37,000] {taskinstance.py:1377} INFO - Executing <Task(PythonOperator): get_last_id> on 2022-11-28 20:02:00+00:00
[2022-12-03 15:12:37,196] {standard_task_runner.py:52} INFO - Started process 1346 to run task
[2022-12-03 15:12:37,356] {standard_task_runner.py:79} INFO - Running: ['airflow', 'tasks', 'run', 'prepare_data', 'get_last_id', 'scheduled__2022-11-28T20:02:00+00:00', '--job-id', '430', '--raw', '--subdir', 'DAGS_FOLDER/prepare_data.py', '--cfg-path', '/tmp/tmpddt81ccj', '--error-file', '/tmp/tmp1j0g79d6']
[2022-12-03 15:12:37,445] {standard_task_runner.py:80} INFO - Job 430: Subtask get_last_id
[2022-12-03 15:12:39,501] {task_command.py:369} INFO - Running <TaskInstance: prepare_data.get_last_id scheduled__2022-11-28T20:02:00+00:00 [running]> on host b41792e8e843
[2022-12-03 15:12:42,226] {taskinstance.py:1571} INFO - Exporting the following env vars:
AIRFLOW_CTX_DAG_OWNER=airflow
AIRFLOW_CTX_DAG_ID=prepare_data
AIRFLOW_CTX_TASK_ID=get_last_id
AIRFLOW_CTX_EXECUTION_DATE=2022-11-28T20:02:00+00:00
AIRFLOW_CTX_TRY_NUMBER=1
AIRFLOW_CTX_DAG_RUN_ID=scheduled__2022-11-28T20:02:00+00:00
[2022-12-03 15:12:42,530] {base.py:68} INFO - Using connection ID 'postgres_default' for task execution.
[2022-12-03 15:12:43,286] {python.py:173} INFO - Done. Returned value was: None
[2022-12-03 15:12:44,155] {taskinstance.py:1400} INFO - Marking task as SUCCESS. dag_id=prepare_data, task_id=get_last_id, execution_date=20221128T200200, start_date=20221203T151235, end_date=20221203T151244
[2022-12-03 15:12:44,657] {local_task_job.py:84} ERROR - Received SIGTERM. Terminating subprocesses
[2022-12-03 15:12:45,328] {process_utils.py:129} INFO - Sending Signals.SIGTERM to group 1346. PIDs of all processes in the group: [1346]
[2022-12-03 15:12:45,329] {process_utils.py:80} INFO - Sending the signal Signals.SIGTERM to group 1346
[2022-12-03 15:12:45,837] {taskinstance.py:1541} ERROR - Received SIGTERM. Terminating subprocesses.
[2022-12-03 15:12:46,501] {standard_task_runner.py:97} ERROR - Failed to execute job 430 for task get_last_id ((psycopg2.InterfaceError) connection already closed
(Background on this error at: http://sqlalche.me/e/14/rvf5); 1346)
[2022-12-03 15:12:51,226] {process_utils.py:75} INFO - Process psutil.Process(pid=1346, status='terminated', exitcode=1, started='15:12:36') (1346) terminated with exit code 1
[2022-12-03 15:12:51,227] {local_task_job.py:156} INFO - Task exited with return code 143
