[2022-12-03 14:46:09,395] {taskinstance.py:1159} INFO - Dependencies all met for <TaskInstance: prepare_data.create_table scheduled__2022-11-28T17:21:00+00:00 [queued]>
[2022-12-03 14:46:09,602] {taskinstance.py:1159} INFO - Dependencies all met for <TaskInstance: prepare_data.create_table scheduled__2022-11-28T17:21:00+00:00 [queued]>
[2022-12-03 14:46:09,602] {taskinstance.py:1356} INFO - 
--------------------------------------------------------------------------------
[2022-12-03 14:46:09,603] {taskinstance.py:1357} INFO - Starting attempt 1 of 1
[2022-12-03 14:46:09,603] {taskinstance.py:1358} INFO - 
--------------------------------------------------------------------------------
[2022-12-03 14:46:10,021] {taskinstance.py:1377} INFO - Executing <Task(PostgresOperator): create_table> on 2022-11-28 17:21:00+00:00
[2022-12-03 14:46:10,107] {standard_task_runner.py:52} INFO - Started process 371 to run task
[2022-12-03 14:46:10,186] {standard_task_runner.py:79} INFO - Running: ['airflow', 'tasks', 'run', 'prepare_data', 'create_table', 'scheduled__2022-11-28T17:21:00+00:00', '--job-id', '49', '--raw', '--subdir', 'DAGS_FOLDER/prepare_data.py', '--cfg-path', '/tmp/tmpizerfux7', '--error-file', '/tmp/tmps7cmvl62']
[2022-12-03 14:46:10,226] {standard_task_runner.py:80} INFO - Job 49: Subtask create_table
[2022-12-03 14:46:11,837] {task_command.py:369} INFO - Running <TaskInstance: prepare_data.create_table scheduled__2022-11-28T17:21:00+00:00 [running]> on host b41792e8e843
[2022-12-03 14:46:13,741] {taskinstance.py:1571} INFO - Exporting the following env vars:
AIRFLOW_CTX_DAG_OWNER=airflow
AIRFLOW_CTX_DAG_ID=prepare_data
AIRFLOW_CTX_TASK_ID=create_table
AIRFLOW_CTX_EXECUTION_DATE=2022-11-28T17:21:00+00:00
AIRFLOW_CTX_TRY_NUMBER=1
AIRFLOW_CTX_DAG_RUN_ID=scheduled__2022-11-28T17:21:00+00:00
[2022-12-03 14:46:14,689] {taskinstance.py:1889} ERROR - Task failed with exception
Traceback (most recent call last):
  File "/home/airflow/.local/lib/python3.7/site-packages/airflow/providers/postgres/operators/postgres.py", line 92, in execute
    self.hook.run(self.sql, self.autocommit, parameters=self.parameters)
  File "/home/airflow/.local/lib/python3.7/site-packages/airflow/hooks/dbapi.py", line 181, in run
    with closing(self.get_conn()) as conn:
  File "/home/airflow/.local/lib/python3.7/site-packages/airflow/providers/postgres/hooks/postgres.py", line 86, in get_conn
    conn = deepcopy(self.connection or self.get_connection(conn_id))
  File "/home/airflow/.local/lib/python3.7/site-packages/airflow/hooks/base.py", line 67, in get_connection
    conn = Connection.get_connection_from_secrets(conn_id)
  File "/home/airflow/.local/lib/python3.7/site-packages/airflow/models/connection.py", line 430, in get_connection_from_secrets
    raise AirflowNotFoundException(f"The conn_id `{conn_id}` isn't defined")
airflow.exceptions.AirflowNotFoundException: The conn_id `postgres_default` isn't defined
[2022-12-03 14:46:14,721] {taskinstance.py:1400} INFO - Marking task as FAILED. dag_id=prepare_data, task_id=create_table, execution_date=20221128T172100, start_date=20221203T144609, end_date=20221203T144614
[2022-12-03 14:46:14,876] {standard_task_runner.py:97} ERROR - Failed to execute job 49 for task create_table (The conn_id `postgres_default` isn't defined; 371)
[2022-12-03 14:46:14,941] {local_task_job.py:156} INFO - Task exited with return code 1
[2022-12-03 14:46:15,732] {local_task_job.py:273} INFO - 0 downstream tasks scheduled from follow-on schedule check
[2022-12-12 12:31:41,882] {taskinstance.py:1159} INFO - Dependencies all met for <TaskInstance: prepare_data.create_table scheduled__2022-11-28T17:21:00+00:00 [queued]>
[2022-12-12 12:31:41,988] {taskinstance.py:1159} INFO - Dependencies all met for <TaskInstance: prepare_data.create_table scheduled__2022-11-28T17:21:00+00:00 [queued]>
[2022-12-12 12:31:41,989] {taskinstance.py:1356} INFO - 
--------------------------------------------------------------------------------
[2022-12-12 12:31:41,989] {taskinstance.py:1357} INFO - Starting attempt 1 of 1
[2022-12-12 12:31:41,989] {taskinstance.py:1358} INFO - 
--------------------------------------------------------------------------------
[2022-12-12 12:31:42,151] {taskinstance.py:1377} INFO - Executing <Task(PostgresOperator): create_table> on 2022-11-28 17:21:00+00:00
[2022-12-12 12:31:42,175] {standard_task_runner.py:52} INFO - Started process 366 to run task
[2022-12-12 12:31:42,206] {standard_task_runner.py:79} INFO - Running: ['airflow', 'tasks', 'run', 'prepare_data', 'create_table', 'scheduled__2022-11-28T17:21:00+00:00', '--job-id', '49', '--raw', '--subdir', 'DAGS_FOLDER/prepare_data.py', '--cfg-path', '/tmp/tmpwlvgxpbr', '--error-file', '/tmp/tmp26284qzv']
[2022-12-12 12:31:42,227] {standard_task_runner.py:80} INFO - Job 49: Subtask create_table
[2022-12-12 12:31:42,957] {task_command.py:369} INFO - Running <TaskInstance: prepare_data.create_table scheduled__2022-11-28T17:21:00+00:00 [running]> on host b778137d8ea6
[2022-12-12 12:31:44,623] {taskinstance.py:1571} INFO - Exporting the following env vars:
AIRFLOW_CTX_DAG_OWNER=airflow
AIRFLOW_CTX_DAG_ID=prepare_data
AIRFLOW_CTX_TASK_ID=create_table
AIRFLOW_CTX_EXECUTION_DATE=2022-11-28T17:21:00+00:00
AIRFLOW_CTX_TRY_NUMBER=1
AIRFLOW_CTX_DAG_RUN_ID=scheduled__2022-11-28T17:21:00+00:00
[2022-12-12 12:31:45,141] {taskinstance.py:1889} ERROR - Task failed with exception
Traceback (most recent call last):
  File "/home/airflow/.local/lib/python3.7/site-packages/airflow/providers/postgres/operators/postgres.py", line 92, in execute
    self.hook.run(self.sql, self.autocommit, parameters=self.parameters)
  File "/home/airflow/.local/lib/python3.7/site-packages/airflow/hooks/dbapi.py", line 181, in run
    with closing(self.get_conn()) as conn:
  File "/home/airflow/.local/lib/python3.7/site-packages/airflow/providers/postgres/hooks/postgres.py", line 86, in get_conn
    conn = deepcopy(self.connection or self.get_connection(conn_id))
  File "/home/airflow/.local/lib/python3.7/site-packages/airflow/hooks/base.py", line 67, in get_connection
    conn = Connection.get_connection_from_secrets(conn_id)
  File "/home/airflow/.local/lib/python3.7/site-packages/airflow/models/connection.py", line 430, in get_connection_from_secrets
    raise AirflowNotFoundException(f"The conn_id `{conn_id}` isn't defined")
airflow.exceptions.AirflowNotFoundException: The conn_id `postgres_default` isn't defined
[2022-12-12 12:31:45,187] {taskinstance.py:1400} INFO - Marking task as FAILED. dag_id=prepare_data, task_id=create_table, execution_date=20221128T172100, start_date=20221212T123141, end_date=20221212T123145
[2022-12-12 12:31:45,360] {standard_task_runner.py:97} ERROR - Failed to execute job 49 for task create_table (The conn_id `postgres_default` isn't defined; 366)
[2022-12-12 12:31:45,444] {local_task_job.py:156} INFO - Task exited with return code 1
[2022-12-12 12:31:46,721] {local_task_job.py:273} INFO - 0 downstream tasks scheduled from follow-on schedule check
[2022-12-12 15:18:55,505] {taskinstance.py:1159} INFO - Dependencies all met for <TaskInstance: prepare_data.create_table scheduled__2022-11-28T17:21:00+00:00 [queued]>
[2022-12-12 15:18:55,934] {taskinstance.py:1159} INFO - Dependencies all met for <TaskInstance: prepare_data.create_table scheduled__2022-11-28T17:21:00+00:00 [queued]>
[2022-12-12 15:18:55,939] {taskinstance.py:1356} INFO - 
--------------------------------------------------------------------------------
[2022-12-12 15:18:55,946] {taskinstance.py:1357} INFO - Starting attempt 1 of 1
[2022-12-12 15:18:55,947] {taskinstance.py:1358} INFO - 
--------------------------------------------------------------------------------
[2022-12-12 15:18:56,844] {taskinstance.py:1377} INFO - Executing <Task(PostgresOperator): create_table> on 2022-11-28 17:21:00+00:00
[2022-12-12 15:18:57,017] {standard_task_runner.py:52} INFO - Started process 421 to run task
[2022-12-12 15:18:57,307] {standard_task_runner.py:79} INFO - Running: ['airflow', 'tasks', 'run', 'prepare_data', 'create_table', 'scheduled__2022-11-28T17:21:00+00:00', '--job-id', '49', '--raw', '--subdir', 'DAGS_FOLDER/prepare_data.py', '--cfg-path', '/tmp/tmp3hux6hsz', '--error-file', '/tmp/tmp_sphryv2']
[2022-12-12 15:18:57,336] {standard_task_runner.py:80} INFO - Job 49: Subtask create_table
[2022-12-12 15:18:59,531] {task_command.py:369} INFO - Running <TaskInstance: prepare_data.create_table scheduled__2022-11-28T17:21:00+00:00 [running]> on host d4eb34144d92
[2022-12-12 15:19:03,394] {taskinstance.py:1571} INFO - Exporting the following env vars:
AIRFLOW_CTX_DAG_OWNER=airflow
AIRFLOW_CTX_DAG_ID=prepare_data
AIRFLOW_CTX_TASK_ID=create_table
AIRFLOW_CTX_EXECUTION_DATE=2022-11-28T17:21:00+00:00
AIRFLOW_CTX_TRY_NUMBER=1
AIRFLOW_CTX_DAG_RUN_ID=scheduled__2022-11-28T17:21:00+00:00
[2022-12-12 15:19:04,743] {taskinstance.py:1889} ERROR - Task failed with exception
Traceback (most recent call last):
  File "/home/airflow/.local/lib/python3.7/site-packages/airflow/providers/postgres/operators/postgres.py", line 92, in execute
    self.hook.run(self.sql, self.autocommit, parameters=self.parameters)
  File "/home/airflow/.local/lib/python3.7/site-packages/airflow/hooks/dbapi.py", line 181, in run
    with closing(self.get_conn()) as conn:
  File "/home/airflow/.local/lib/python3.7/site-packages/airflow/providers/postgres/hooks/postgres.py", line 86, in get_conn
    conn = deepcopy(self.connection or self.get_connection(conn_id))
  File "/home/airflow/.local/lib/python3.7/site-packages/airflow/hooks/base.py", line 67, in get_connection
    conn = Connection.get_connection_from_secrets(conn_id)
  File "/home/airflow/.local/lib/python3.7/site-packages/airflow/models/connection.py", line 430, in get_connection_from_secrets
    raise AirflowNotFoundException(f"The conn_id `{conn_id}` isn't defined")
airflow.exceptions.AirflowNotFoundException: The conn_id `postgres_default` isn't defined
[2022-12-12 15:19:04,973] {taskinstance.py:1400} INFO - Marking task as FAILED. dag_id=prepare_data, task_id=create_table, execution_date=20221128T172100, start_date=20221212T151855, end_date=20221212T151904
[2022-12-12 15:19:05,333] {standard_task_runner.py:97} ERROR - Failed to execute job 49 for task create_table (The conn_id `postgres_default` isn't defined; 421)
[2022-12-12 15:19:05,448] {local_task_job.py:156} INFO - Task exited with return code 1
[2022-12-12 15:19:07,721] {local_task_job.py:273} INFO - 0 downstream tasks scheduled from follow-on schedule check
