[2022-12-03 15:08:55,428] {taskinstance.py:1159} INFO - Dependencies all met for <TaskInstance: prepare_data.create_table scheduled__2022-11-28T19:42:00+00:00 [queued]>
[2022-12-03 15:08:55,817] {taskinstance.py:1159} INFO - Dependencies all met for <TaskInstance: prepare_data.create_table scheduled__2022-11-28T19:42:00+00:00 [queued]>
[2022-12-03 15:08:55,818] {taskinstance.py:1356} INFO - 
--------------------------------------------------------------------------------
[2022-12-03 15:08:55,818] {taskinstance.py:1357} INFO - Starting attempt 1 of 1
[2022-12-03 15:08:55,818] {taskinstance.py:1358} INFO - 
--------------------------------------------------------------------------------
[2022-12-03 15:08:56,626] {taskinstance.py:1377} INFO - Executing <Task(PostgresOperator): create_table> on 2022-11-28 19:42:00+00:00
[2022-12-03 15:08:56,732] {standard_task_runner.py:52} INFO - Started process 1181 to run task
[2022-12-03 15:08:56,846] {standard_task_runner.py:79} INFO - Running: ['airflow', 'tasks', 'run', 'prepare_data', 'create_table', 'scheduled__2022-11-28T19:42:00+00:00', '--job-id', '363', '--raw', '--subdir', 'DAGS_FOLDER/prepare_data.py', '--cfg-path', '/tmp/tmp3s7g_6af', '--error-file', '/tmp/tmpqx8t53dn']
[2022-12-03 15:08:57,070] {standard_task_runner.py:80} INFO - Job 363: Subtask create_table
[2022-12-03 15:08:59,808] {task_command.py:369} INFO - Running <TaskInstance: prepare_data.create_table scheduled__2022-11-28T19:42:00+00:00 [running]> on host b41792e8e843
[2022-12-03 15:09:05,678] {taskinstance.py:1571} INFO - Exporting the following env vars:
AIRFLOW_CTX_DAG_OWNER=airflow
AIRFLOW_CTX_DAG_ID=prepare_data
AIRFLOW_CTX_TASK_ID=create_table
AIRFLOW_CTX_EXECUTION_DATE=2022-11-28T19:42:00+00:00
AIRFLOW_CTX_TRY_NUMBER=1
AIRFLOW_CTX_DAG_RUN_ID=scheduled__2022-11-28T19:42:00+00:00
[2022-12-03 15:09:06,335] {base.py:68} INFO - Using connection ID 'postgres_default' for task execution.
[2022-12-03 15:09:06,577] {dbapi.py:208} INFO - Running statement: CREATE TABLE IF NOT EXISTS prepared_data (
	id SERIAL,
	sensor_id BIGINT,
	longitude FLOAT,
	latitude FLOAT,
	controller_id BIGINT,
	datetime TIMESTAMP WITH TIME ZONE,
	temperature INTEGER
);, parameters: None
[2022-12-03 15:09:06,683] {postgres.py:94} INFO - NOTICE:  relation "prepared_data" already exists, skipping

[2022-12-03 15:09:07,899] {taskinstance.py:1400} INFO - Marking task as SUCCESS. dag_id=prepare_data, task_id=create_table, execution_date=20221128T194200, start_date=20221203T150855, end_date=20221203T150907
[2022-12-03 15:09:08,595] {local_task_job.py:156} INFO - Task exited with return code 0
[2022-12-03 15:09:11,378] {local_task_job.py:273} INFO - 1 downstream tasks scheduled from follow-on schedule check
[2022-12-12 12:36:28,044] {taskinstance.py:1159} INFO - Dependencies all met for <TaskInstance: prepare_data.create_table scheduled__2022-11-28T19:42:00+00:00 [queued]>
[2022-12-12 12:36:28,081] {taskinstance.py:1159} INFO - Dependencies all met for <TaskInstance: prepare_data.create_table scheduled__2022-11-28T19:42:00+00:00 [queued]>
[2022-12-12 12:36:28,081] {taskinstance.py:1356} INFO - 
--------------------------------------------------------------------------------
[2022-12-12 12:36:28,081] {taskinstance.py:1357} INFO - Starting attempt 1 of 1
[2022-12-12 12:36:28,081] {taskinstance.py:1358} INFO - 
--------------------------------------------------------------------------------
[2022-12-12 12:36:28,132] {taskinstance.py:1377} INFO - Executing <Task(PostgresOperator): create_table> on 2022-11-28 19:42:00+00:00
[2022-12-12 12:36:28,141] {standard_task_runner.py:52} INFO - Started process 692 to run task
[2022-12-12 12:36:28,157] {standard_task_runner.py:79} INFO - Running: ['airflow', 'tasks', 'run', 'prepare_data', 'create_table', 'scheduled__2022-11-28T19:42:00+00:00', '--job-id', '190', '--raw', '--subdir', 'DAGS_FOLDER/prepare_data.py', '--cfg-path', '/tmp/tmpa95omvgv', '--error-file', '/tmp/tmp769k7b1m']
[2022-12-12 12:36:28,161] {standard_task_runner.py:80} INFO - Job 190: Subtask create_table
[2022-12-12 12:36:28,351] {task_command.py:369} INFO - Running <TaskInstance: prepare_data.create_table scheduled__2022-11-28T19:42:00+00:00 [running]> on host b778137d8ea6
[2022-12-12 12:36:28,656] {taskinstance.py:1571} INFO - Exporting the following env vars:
AIRFLOW_CTX_DAG_OWNER=airflow
AIRFLOW_CTX_DAG_ID=prepare_data
AIRFLOW_CTX_TASK_ID=create_table
AIRFLOW_CTX_EXECUTION_DATE=2022-11-28T19:42:00+00:00
AIRFLOW_CTX_TRY_NUMBER=1
AIRFLOW_CTX_DAG_RUN_ID=scheduled__2022-11-28T19:42:00+00:00
[2022-12-12 12:36:28,744] {taskinstance.py:1889} ERROR - Task failed with exception
Traceback (most recent call last):
  File "/home/airflow/.local/lib/python3.7/site-packages/airflow/providers/postgres/operators/postgres.py", line 92, in execute
    self.hook.run(self.sql, self.autocommit, parameters=self.parameters)
  File "/home/airflow/.local/lib/python3.7/site-packages/airflow/hooks/dbapi.py", line 181, in run
    with closing(self.get_conn()) as conn:
  File "/home/airflow/.local/lib/python3.7/site-packages/airflow/providers/postgres/hooks/postgres.py", line 86, in get_conn
    conn = deepcopy(self.connection or self.get_connection(conn_id))
  File "/home/airflow/.local/lib/python3.7/site-packages/airflow/hooks/base.py", line 67, in get_connection
    conn = Connection.get_connection_from_secrets(conn_id)
  File "/home/airflow/.local/lib/python3.7/site-packages/airflow/models/connection.py", line 430, in get_connection_from_secrets
    raise AirflowNotFoundException(f"The conn_id `{conn_id}` isn't defined")
airflow.exceptions.AirflowNotFoundException: The conn_id `postgres_default` isn't defined
[2022-12-12 12:36:28,751] {taskinstance.py:1400} INFO - Marking task as FAILED. dag_id=prepare_data, task_id=create_table, execution_date=20221128T194200, start_date=20221212T123628, end_date=20221212T123628
[2022-12-12 12:36:28,813] {standard_task_runner.py:97} ERROR - Failed to execute job 190 for task create_table (The conn_id `postgres_default` isn't defined; 692)
[2022-12-12 12:36:28,866] {local_task_job.py:156} INFO - Task exited with return code 1
[2022-12-12 12:36:28,983] {local_task_job.py:273} INFO - 0 downstream tasks scheduled from follow-on schedule check
