[2022-12-03 14:43:31,755] {taskinstance.py:1159} INFO - Dependencies all met for <TaskInstance: prepare_data.create_table scheduled__2022-11-28T16:41:00+00:00 [queued]>
[2022-12-03 14:43:31,922] {taskinstance.py:1159} INFO - Dependencies all met for <TaskInstance: prepare_data.create_table scheduled__2022-11-28T16:41:00+00:00 [queued]>
[2022-12-03 14:43:31,922] {taskinstance.py:1356} INFO - 
--------------------------------------------------------------------------------
[2022-12-03 14:43:31,923] {taskinstance.py:1357} INFO - Starting attempt 1 of 1
[2022-12-03 14:43:31,923] {taskinstance.py:1358} INFO - 
--------------------------------------------------------------------------------
[2022-12-03 14:43:32,364] {taskinstance.py:1377} INFO - Executing <Task(PostgresOperator): create_table> on 2022-11-28 16:41:00+00:00
[2022-12-03 14:43:32,425] {standard_task_runner.py:52} INFO - Started process 270 to run task
[2022-12-03 14:43:32,476] {standard_task_runner.py:79} INFO - Running: ['airflow', 'tasks', 'run', 'prepare_data', 'create_table', 'scheduled__2022-11-28T16:41:00+00:00', '--job-id', '9', '--raw', '--subdir', 'DAGS_FOLDER/prepare_data.py', '--cfg-path', '/tmp/tmpy3sjtd2f', '--error-file', '/tmp/tmp1kw0lzfd']
[2022-12-03 14:43:32,523] {standard_task_runner.py:80} INFO - Job 9: Subtask create_table
[2022-12-03 14:43:33,859] {task_command.py:369} INFO - Running <TaskInstance: prepare_data.create_table scheduled__2022-11-28T16:41:00+00:00 [running]> on host b41792e8e843
[2022-12-03 14:43:37,376] {taskinstance.py:1571} INFO - Exporting the following env vars:
AIRFLOW_CTX_DAG_OWNER=airflow
AIRFLOW_CTX_DAG_ID=prepare_data
AIRFLOW_CTX_TASK_ID=create_table
AIRFLOW_CTX_EXECUTION_DATE=2022-11-28T16:41:00+00:00
AIRFLOW_CTX_TRY_NUMBER=1
AIRFLOW_CTX_DAG_RUN_ID=scheduled__2022-11-28T16:41:00+00:00
[2022-12-03 14:43:38,844] {taskinstance.py:1889} ERROR - Task failed with exception
Traceback (most recent call last):
  File "/home/airflow/.local/lib/python3.7/site-packages/airflow/providers/postgres/operators/postgres.py", line 92, in execute
    self.hook.run(self.sql, self.autocommit, parameters=self.parameters)
  File "/home/airflow/.local/lib/python3.7/site-packages/airflow/hooks/dbapi.py", line 181, in run
    with closing(self.get_conn()) as conn:
  File "/home/airflow/.local/lib/python3.7/site-packages/airflow/providers/postgres/hooks/postgres.py", line 86, in get_conn
    conn = deepcopy(self.connection or self.get_connection(conn_id))
  File "/home/airflow/.local/lib/python3.7/site-packages/airflow/hooks/base.py", line 67, in get_connection
    conn = Connection.get_connection_from_secrets(conn_id)
  File "/home/airflow/.local/lib/python3.7/site-packages/airflow/models/connection.py", line 430, in get_connection_from_secrets
    raise AirflowNotFoundException(f"The conn_id `{conn_id}` isn't defined")
airflow.exceptions.AirflowNotFoundException: The conn_id `postgres_default` isn't defined
[2022-12-03 14:43:38,948] {taskinstance.py:1400} INFO - Marking task as FAILED. dag_id=prepare_data, task_id=create_table, execution_date=20221128T164100, start_date=20221203T144331, end_date=20221203T144338
[2022-12-03 14:43:39,590] {standard_task_runner.py:97} ERROR - Failed to execute job 9 for task create_table (The conn_id `postgres_default` isn't defined; 270)
[2022-12-03 14:43:39,713] {local_task_job.py:156} INFO - Task exited with return code 1
[2022-12-03 14:43:42,126] {local_task_job.py:273} INFO - 0 downstream tasks scheduled from follow-on schedule check
[2022-12-12 12:27:35,627] {taskinstance.py:1159} INFO - Dependencies all met for <TaskInstance: prepare_data.create_table scheduled__2022-11-28T16:41:00+00:00 [queued]>
[2022-12-12 12:27:36,372] {taskinstance.py:1159} INFO - Dependencies all met for <TaskInstance: prepare_data.create_table scheduled__2022-11-28T16:41:00+00:00 [queued]>
[2022-12-12 12:27:36,375] {taskinstance.py:1356} INFO - 
--------------------------------------------------------------------------------
[2022-12-12 12:27:36,375] {taskinstance.py:1357} INFO - Starting attempt 1 of 1
[2022-12-12 12:27:36,375] {taskinstance.py:1358} INFO - 
--------------------------------------------------------------------------------
[2022-12-12 12:27:37,571] {taskinstance.py:1377} INFO - Executing <Task(PostgresOperator): create_table> on 2022-11-28 16:41:00+00:00
[2022-12-12 12:27:37,631] {standard_task_runner.py:52} INFO - Started process 249 to run task
[2022-12-12 12:27:37,814] {standard_task_runner.py:79} INFO - Running: ['airflow', 'tasks', 'run', 'prepare_data', 'create_table', 'scheduled__2022-11-28T16:41:00+00:00', '--job-id', '9', '--raw', '--subdir', 'DAGS_FOLDER/prepare_data.py', '--cfg-path', '/tmp/tmpmkbtfyc9', '--error-file', '/tmp/tmpjfsf7ho8']
[2022-12-12 12:27:37,867] {standard_task_runner.py:80} INFO - Job 9: Subtask create_table
[2022-12-12 12:27:39,688] {task_command.py:369} INFO - Running <TaskInstance: prepare_data.create_table scheduled__2022-11-28T16:41:00+00:00 [running]> on host b778137d8ea6
[2022-12-12 12:27:42,736] {taskinstance.py:1571} INFO - Exporting the following env vars:
AIRFLOW_CTX_DAG_OWNER=airflow
AIRFLOW_CTX_DAG_ID=prepare_data
AIRFLOW_CTX_TASK_ID=create_table
AIRFLOW_CTX_EXECUTION_DATE=2022-11-28T16:41:00+00:00
AIRFLOW_CTX_TRY_NUMBER=1
AIRFLOW_CTX_DAG_RUN_ID=scheduled__2022-11-28T16:41:00+00:00
[2022-12-12 12:27:44,099] {taskinstance.py:1889} ERROR - Task failed with exception
Traceback (most recent call last):
  File "/home/airflow/.local/lib/python3.7/site-packages/airflow/providers/postgres/operators/postgres.py", line 92, in execute
    self.hook.run(self.sql, self.autocommit, parameters=self.parameters)
  File "/home/airflow/.local/lib/python3.7/site-packages/airflow/hooks/dbapi.py", line 181, in run
    with closing(self.get_conn()) as conn:
  File "/home/airflow/.local/lib/python3.7/site-packages/airflow/providers/postgres/hooks/postgres.py", line 86, in get_conn
    conn = deepcopy(self.connection or self.get_connection(conn_id))
  File "/home/airflow/.local/lib/python3.7/site-packages/airflow/hooks/base.py", line 67, in get_connection
    conn = Connection.get_connection_from_secrets(conn_id)
  File "/home/airflow/.local/lib/python3.7/site-packages/airflow/models/connection.py", line 430, in get_connection_from_secrets
    raise AirflowNotFoundException(f"The conn_id `{conn_id}` isn't defined")
airflow.exceptions.AirflowNotFoundException: The conn_id `postgres_default` isn't defined
[2022-12-12 12:27:44,158] {taskinstance.py:1400} INFO - Marking task as FAILED. dag_id=prepare_data, task_id=create_table, execution_date=20221128T164100, start_date=20221212T122735, end_date=20221212T122744
[2022-12-12 12:27:44,277] {standard_task_runner.py:97} ERROR - Failed to execute job 9 for task create_table (The conn_id `postgres_default` isn't defined; 249)
[2022-12-12 12:27:44,389] {local_task_job.py:156} INFO - Task exited with return code 1
[2022-12-12 12:27:45,399] {local_task_job.py:273} INFO - 0 downstream tasks scheduled from follow-on schedule check
[2022-12-12 15:11:45,296] {taskinstance.py:1159} INFO - Dependencies all met for <TaskInstance: prepare_data.create_table scheduled__2022-11-28T16:41:00+00:00 [queued]>
[2022-12-12 15:11:45,889] {taskinstance.py:1159} INFO - Dependencies all met for <TaskInstance: prepare_data.create_table scheduled__2022-11-28T16:41:00+00:00 [queued]>
[2022-12-12 15:11:45,890] {taskinstance.py:1356} INFO - 
--------------------------------------------------------------------------------
[2022-12-12 15:11:45,890] {taskinstance.py:1357} INFO - Starting attempt 1 of 1
[2022-12-12 15:11:45,973] {taskinstance.py:1358} INFO - 
--------------------------------------------------------------------------------
[2022-12-12 15:11:47,194] {taskinstance.py:1377} INFO - Executing <Task(PostgresOperator): create_table> on 2022-11-28 16:41:00+00:00
[2022-12-12 15:11:47,564] {standard_task_runner.py:52} INFO - Started process 284 to run task
[2022-12-12 15:11:48,118] {standard_task_runner.py:79} INFO - Running: ['airflow', 'tasks', 'run', 'prepare_data', 'create_table', 'scheduled__2022-11-28T16:41:00+00:00', '--job-id', '9', '--raw', '--subdir', 'DAGS_FOLDER/prepare_data.py', '--cfg-path', '/tmp/tmpofdd2lb3', '--error-file', '/tmp/tmpgapktp_r']
[2022-12-12 15:11:48,188] {standard_task_runner.py:80} INFO - Job 9: Subtask create_table
[2022-12-12 15:11:52,278] {task_command.py:369} INFO - Running <TaskInstance: prepare_data.create_table scheduled__2022-11-28T16:41:00+00:00 [running]> on host d4eb34144d92
[2022-12-12 15:11:55,929] {taskinstance.py:1571} INFO - Exporting the following env vars:
AIRFLOW_CTX_DAG_OWNER=airflow
AIRFLOW_CTX_DAG_ID=prepare_data
AIRFLOW_CTX_TASK_ID=create_table
AIRFLOW_CTX_EXECUTION_DATE=2022-11-28T16:41:00+00:00
AIRFLOW_CTX_TRY_NUMBER=1
AIRFLOW_CTX_DAG_RUN_ID=scheduled__2022-11-28T16:41:00+00:00
[2022-12-12 15:11:56,330] {taskinstance.py:1889} ERROR - Task failed with exception
Traceback (most recent call last):
  File "/home/airflow/.local/lib/python3.7/site-packages/airflow/providers/postgres/operators/postgres.py", line 92, in execute
    self.hook.run(self.sql, self.autocommit, parameters=self.parameters)
  File "/home/airflow/.local/lib/python3.7/site-packages/airflow/hooks/dbapi.py", line 181, in run
    with closing(self.get_conn()) as conn:
  File "/home/airflow/.local/lib/python3.7/site-packages/airflow/providers/postgres/hooks/postgres.py", line 86, in get_conn
    conn = deepcopy(self.connection or self.get_connection(conn_id))
  File "/home/airflow/.local/lib/python3.7/site-packages/airflow/hooks/base.py", line 67, in get_connection
    conn = Connection.get_connection_from_secrets(conn_id)
  File "/home/airflow/.local/lib/python3.7/site-packages/airflow/models/connection.py", line 430, in get_connection_from_secrets
    raise AirflowNotFoundException(f"The conn_id `{conn_id}` isn't defined")
airflow.exceptions.AirflowNotFoundException: The conn_id `postgres_default` isn't defined
[2022-12-12 15:11:56,378] {taskinstance.py:1400} INFO - Marking task as FAILED. dag_id=prepare_data, task_id=create_table, execution_date=20221128T164100, start_date=20221212T151145, end_date=20221212T151156
[2022-12-12 15:11:56,681] {standard_task_runner.py:97} ERROR - Failed to execute job 9 for task create_table (The conn_id `postgres_default` isn't defined; 284)
[2022-12-12 15:11:56,727] {local_task_job.py:156} INFO - Task exited with return code 1
[2022-12-12 15:11:57,779] {local_task_job.py:273} INFO - 0 downstream tasks scheduled from follow-on schedule check
