[2022-12-12 12:43:01,753] {taskinstance.py:1159} INFO - Dependencies all met for <TaskInstance: prepare_data.create_table scheduled__2022-11-28T21:37:00+00:00 [queued]>
[2022-12-12 12:43:02,179] {taskinstance.py:1159} INFO - Dependencies all met for <TaskInstance: prepare_data.create_table scheduled__2022-11-28T21:37:00+00:00 [queued]>
[2022-12-12 12:43:02,179] {taskinstance.py:1356} INFO - 
--------------------------------------------------------------------------------
[2022-12-12 12:43:02,207] {taskinstance.py:1357} INFO - Starting attempt 1 of 1
[2022-12-12 12:43:02,207] {taskinstance.py:1358} INFO - 
--------------------------------------------------------------------------------
[2022-12-12 12:43:03,012] {taskinstance.py:1377} INFO - Executing <Task(PostgresOperator): create_table> on 2022-11-28 21:37:00+00:00
[2022-12-12 12:43:03,081] {standard_task_runner.py:52} INFO - Started process 983 to run task
[2022-12-12 12:43:03,448] {standard_task_runner.py:79} INFO - Running: ['airflow', 'tasks', 'run', 'prepare_data', 'create_table', 'scheduled__2022-11-28T21:37:00+00:00', '--job-id', '305', '--raw', '--subdir', 'DAGS_FOLDER/prepare_data.py', '--cfg-path', '/tmp/tmpx2m3a6w5', '--error-file', '/tmp/tmp2aysjozc']
[2022-12-12 12:43:03,612] {standard_task_runner.py:80} INFO - Job 305: Subtask create_table
[2022-12-12 12:43:05,385] {task_command.py:369} INFO - Running <TaskInstance: prepare_data.create_table scheduled__2022-11-28T21:37:00+00:00 [running]> on host b778137d8ea6
[2022-12-12 12:43:08,047] {taskinstance.py:1571} INFO - Exporting the following env vars:
AIRFLOW_CTX_DAG_OWNER=airflow
AIRFLOW_CTX_DAG_ID=prepare_data
AIRFLOW_CTX_TASK_ID=create_table
AIRFLOW_CTX_EXECUTION_DATE=2022-11-28T21:37:00+00:00
AIRFLOW_CTX_TRY_NUMBER=1
AIRFLOW_CTX_DAG_RUN_ID=scheduled__2022-11-28T21:37:00+00:00
[2022-12-12 12:43:08,800] {taskinstance.py:1889} ERROR - Task failed with exception
Traceback (most recent call last):
  File "/home/airflow/.local/lib/python3.7/site-packages/airflow/providers/postgres/operators/postgres.py", line 92, in execute
    self.hook.run(self.sql, self.autocommit, parameters=self.parameters)
  File "/home/airflow/.local/lib/python3.7/site-packages/airflow/hooks/dbapi.py", line 181, in run
    with closing(self.get_conn()) as conn:
  File "/home/airflow/.local/lib/python3.7/site-packages/airflow/providers/postgres/hooks/postgres.py", line 86, in get_conn
    conn = deepcopy(self.connection or self.get_connection(conn_id))
  File "/home/airflow/.local/lib/python3.7/site-packages/airflow/hooks/base.py", line 67, in get_connection
    conn = Connection.get_connection_from_secrets(conn_id)
  File "/home/airflow/.local/lib/python3.7/site-packages/airflow/models/connection.py", line 430, in get_connection_from_secrets
    raise AirflowNotFoundException(f"The conn_id `{conn_id}` isn't defined")
airflow.exceptions.AirflowNotFoundException: The conn_id `postgres_default` isn't defined
[2022-12-12 12:43:08,930] {taskinstance.py:1400} INFO - Marking task as FAILED. dag_id=prepare_data, task_id=create_table, execution_date=20221128T213700, start_date=20221212T124301, end_date=20221212T124308
[2022-12-12 12:43:09,308] {standard_task_runner.py:97} ERROR - Failed to execute job 305 for task create_table (The conn_id `postgres_default` isn't defined; 983)
[2022-12-12 12:43:09,421] {local_task_job.py:156} INFO - Task exited with return code 1
[2022-12-12 12:43:10,522] {local_task_job.py:273} INFO - 0 downstream tasks scheduled from follow-on schedule check
