[2022-12-03 14:58:44,461] {taskinstance.py:1159} INFO - Dependencies all met for <TaskInstance: prepare_data.create_table scheduled__2022-11-28T18:51:00+00:00 [queued]>
[2022-12-03 14:58:45,355] {taskinstance.py:1159} INFO - Dependencies all met for <TaskInstance: prepare_data.create_table scheduled__2022-11-28T18:51:00+00:00 [queued]>
[2022-12-03 14:58:45,356] {taskinstance.py:1356} INFO - 
--------------------------------------------------------------------------------
[2022-12-03 14:58:45,356] {taskinstance.py:1357} INFO - Starting attempt 1 of 1
[2022-12-03 14:58:45,356] {taskinstance.py:1358} INFO - 
--------------------------------------------------------------------------------
[2022-12-03 14:58:46,724] {taskinstance.py:1377} INFO - Executing <Task(PostgresOperator): create_table> on 2022-11-28 18:51:00+00:00
[2022-12-03 14:58:46,839] {standard_task_runner.py:52} INFO - Started process 785 to run task
[2022-12-03 14:58:47,391] {standard_task_runner.py:79} INFO - Running: ['airflow', 'tasks', 'run', 'prepare_data', 'create_table', 'scheduled__2022-11-28T18:51:00+00:00', '--job-id', '208', '--raw', '--subdir', 'DAGS_FOLDER/prepare_data.py', '--cfg-path', '/tmp/tmpke8x7fcn', '--error-file', '/tmp/tmpitg58jc3']
[2022-12-03 14:58:47,464] {standard_task_runner.py:80} INFO - Job 208: Subtask create_table
[2022-12-03 14:58:49,926] {task_command.py:369} INFO - Running <TaskInstance: prepare_data.create_table scheduled__2022-11-28T18:51:00+00:00 [running]> on host b41792e8e843
[2022-12-03 14:58:56,611] {taskinstance.py:1571} INFO - Exporting the following env vars:
AIRFLOW_CTX_DAG_OWNER=airflow
AIRFLOW_CTX_DAG_ID=prepare_data
AIRFLOW_CTX_TASK_ID=create_table
AIRFLOW_CTX_EXECUTION_DATE=2022-11-28T18:51:00+00:00
AIRFLOW_CTX_TRY_NUMBER=1
AIRFLOW_CTX_DAG_RUN_ID=scheduled__2022-11-28T18:51:00+00:00
[2022-12-03 14:58:57,294] {base.py:68} INFO - Using connection ID 'postgres_default' for task execution.
[2022-12-03 14:58:57,471] {dbapi.py:208} INFO - Running statement: CREATE TABLE IF NOT EXISTS prepared_data (
	id SERIAL,
	sensor_id BIGINT,
	longitude FLOAT,
	latitude FLOAT,
	controller_id BIGINT,
	datetime TIMESTAMP WITH TIME ZONE,
	temperature INTEGER
);, parameters: None
[2022-12-03 14:58:57,509] {postgres.py:94} INFO - NOTICE:  relation "prepared_data" already exists, skipping

[2022-12-03 14:59:02,370] {taskinstance.py:1400} INFO - Marking task as SUCCESS. dag_id=prepare_data, task_id=create_table, execution_date=20221128T185100, start_date=20221203T145844, end_date=20221203T145902
[2022-12-03 14:59:03,303] {local_task_job.py:156} INFO - Task exited with return code 0
[2022-12-03 14:59:06,121] {local_task_job.py:273} INFO - 1 downstream tasks scheduled from follow-on schedule check
[2022-12-12 12:34:41,356] {taskinstance.py:1159} INFO - Dependencies all met for <TaskInstance: prepare_data.create_table scheduled__2022-11-28T18:51:00+00:00 [queued]>
[2022-12-12 12:34:41,850] {taskinstance.py:1159} INFO - Dependencies all met for <TaskInstance: prepare_data.create_table scheduled__2022-11-28T18:51:00+00:00 [queued]>
[2022-12-12 12:34:41,850] {taskinstance.py:1356} INFO - 
--------------------------------------------------------------------------------
[2022-12-12 12:34:41,865] {taskinstance.py:1357} INFO - Starting attempt 1 of 1
[2022-12-12 12:34:41,865] {taskinstance.py:1358} INFO - 
--------------------------------------------------------------------------------
[2022-12-12 12:34:42,475] {taskinstance.py:1377} INFO - Executing <Task(PostgresOperator): create_table> on 2022-11-28 18:51:00+00:00
[2022-12-12 12:34:42,572] {standard_task_runner.py:52} INFO - Started process 576 to run task
[2022-12-12 12:34:42,791] {standard_task_runner.py:79} INFO - Running: ['airflow', 'tasks', 'run', 'prepare_data', 'create_table', 'scheduled__2022-11-28T18:51:00+00:00', '--job-id', '139', '--raw', '--subdir', 'DAGS_FOLDER/prepare_data.py', '--cfg-path', '/tmp/tmpp5s2xnyq', '--error-file', '/tmp/tmp5gcdewrr']
[2022-12-12 12:34:42,843] {standard_task_runner.py:80} INFO - Job 139: Subtask create_table
[2022-12-12 12:34:44,225] {task_command.py:369} INFO - Running <TaskInstance: prepare_data.create_table scheduled__2022-11-28T18:51:00+00:00 [running]> on host b778137d8ea6
[2022-12-12 12:34:46,418] {taskinstance.py:1571} INFO - Exporting the following env vars:
AIRFLOW_CTX_DAG_OWNER=airflow
AIRFLOW_CTX_DAG_ID=prepare_data
AIRFLOW_CTX_TASK_ID=create_table
AIRFLOW_CTX_EXECUTION_DATE=2022-11-28T18:51:00+00:00
AIRFLOW_CTX_TRY_NUMBER=1
AIRFLOW_CTX_DAG_RUN_ID=scheduled__2022-11-28T18:51:00+00:00
[2022-12-12 12:34:48,313] {taskinstance.py:1889} ERROR - Task failed with exception
Traceback (most recent call last):
  File "/home/airflow/.local/lib/python3.7/site-packages/airflow/providers/postgres/operators/postgres.py", line 92, in execute
    self.hook.run(self.sql, self.autocommit, parameters=self.parameters)
  File "/home/airflow/.local/lib/python3.7/site-packages/airflow/hooks/dbapi.py", line 181, in run
    with closing(self.get_conn()) as conn:
  File "/home/airflow/.local/lib/python3.7/site-packages/airflow/providers/postgres/hooks/postgres.py", line 86, in get_conn
    conn = deepcopy(self.connection or self.get_connection(conn_id))
  File "/home/airflow/.local/lib/python3.7/site-packages/airflow/hooks/base.py", line 67, in get_connection
    conn = Connection.get_connection_from_secrets(conn_id)
  File "/home/airflow/.local/lib/python3.7/site-packages/airflow/models/connection.py", line 430, in get_connection_from_secrets
    raise AirflowNotFoundException(f"The conn_id `{conn_id}` isn't defined")
airflow.exceptions.AirflowNotFoundException: The conn_id `postgres_default` isn't defined
[2022-12-12 12:34:48,557] {taskinstance.py:1400} INFO - Marking task as FAILED. dag_id=prepare_data, task_id=create_table, execution_date=20221128T185100, start_date=20221212T123441, end_date=20221212T123448
[2022-12-12 12:34:48,857] {standard_task_runner.py:97} ERROR - Failed to execute job 139 for task create_table (The conn_id `postgres_default` isn't defined; 576)
[2022-12-12 12:34:48,973] {local_task_job.py:156} INFO - Task exited with return code 1
[2022-12-12 12:34:49,857] {local_task_job.py:273} INFO - 0 downstream tasks scheduled from follow-on schedule check
