[2022-12-03 14:57:36,767] {taskinstance.py:1159} INFO - Dependencies all met for <TaskInstance: prepare_data.create_table scheduled__2022-11-28T18:40:00+00:00 [queued]>
[2022-12-03 14:57:37,343] {taskinstance.py:1159} INFO - Dependencies all met for <TaskInstance: prepare_data.create_table scheduled__2022-11-28T18:40:00+00:00 [queued]>
[2022-12-03 14:57:37,343] {taskinstance.py:1356} INFO - 
--------------------------------------------------------------------------------
[2022-12-03 14:57:37,344] {taskinstance.py:1357} INFO - Starting attempt 1 of 1
[2022-12-03 14:57:37,344] {taskinstance.py:1358} INFO - 
--------------------------------------------------------------------------------
[2022-12-03 14:57:37,853] {taskinstance.py:1377} INFO - Executing <Task(PostgresOperator): create_table> on 2022-11-28 18:40:00+00:00
[2022-12-03 14:57:37,949] {standard_task_runner.py:52} INFO - Started process 726 to run task
[2022-12-03 14:57:38,086] {standard_task_runner.py:79} INFO - Running: ['airflow', 'tasks', 'run', 'prepare_data', 'create_table', 'scheduled__2022-11-28T18:40:00+00:00', '--job-id', '183', '--raw', '--subdir', 'DAGS_FOLDER/prepare_data.py', '--cfg-path', '/tmp/tmp4fcm9j4c', '--error-file', '/tmp/tmpr6_nfj7l']
[2022-12-03 14:57:38,115] {standard_task_runner.py:80} INFO - Job 183: Subtask create_table
[2022-12-03 14:57:40,138] {task_command.py:369} INFO - Running <TaskInstance: prepare_data.create_table scheduled__2022-11-28T18:40:00+00:00 [running]> on host b41792e8e843
[2022-12-03 14:57:42,826] {taskinstance.py:1571} INFO - Exporting the following env vars:
AIRFLOW_CTX_DAG_OWNER=airflow
AIRFLOW_CTX_DAG_ID=prepare_data
AIRFLOW_CTX_TASK_ID=create_table
AIRFLOW_CTX_EXECUTION_DATE=2022-11-28T18:40:00+00:00
AIRFLOW_CTX_TRY_NUMBER=1
AIRFLOW_CTX_DAG_RUN_ID=scheduled__2022-11-28T18:40:00+00:00
[2022-12-03 14:57:43,023] {base.py:68} INFO - Using connection ID 'postgres_default' for task execution.
[2022-12-03 14:57:43,091] {dbapi.py:208} INFO - Running statement: CREATE TABLE IF NOT EXISTS prepared_data (
	id SERIAL,
	sensor_id BIGINT,
	longitude FLOAT,
	latitude FLOAT,
	controller_id BIGINT,
	datetime TIMESTAMP WITH TIME ZONE,
	temperature INTEGER
);, parameters: None
[2022-12-03 14:57:43,100] {postgres.py:94} INFO - NOTICE:  relation "prepared_data" already exists, skipping

[2022-12-03 14:57:43,557] {taskinstance.py:1400} INFO - Marking task as SUCCESS. dag_id=prepare_data, task_id=create_table, execution_date=20221128T184000, start_date=20221203T145736, end_date=20221203T145743
[2022-12-03 14:57:43,904] {local_task_job.py:221} WARNING - State of this instance has been externally set to success. Terminating instance.
[2022-12-03 14:57:43,932] {process_utils.py:129} INFO - Sending Signals.SIGTERM to group 726. PIDs of all processes in the group: [726]
[2022-12-03 14:57:43,968] {process_utils.py:80} INFO - Sending the signal Signals.SIGTERM to group 726
[2022-12-03 14:57:43,984] {process_utils.py:75} INFO - Process psutil.Process(pid=726, status='terminated', exitcode=0, started='14:57:37') (726) terminated with exit code 0
[2022-12-12 12:34:20,724] {taskinstance.py:1159} INFO - Dependencies all met for <TaskInstance: prepare_data.create_table scheduled__2022-11-28T18:40:00+00:00 [queued]>
[2022-12-12 12:34:20,814] {taskinstance.py:1159} INFO - Dependencies all met for <TaskInstance: prepare_data.create_table scheduled__2022-11-28T18:40:00+00:00 [queued]>
[2022-12-12 12:34:20,819] {taskinstance.py:1356} INFO - 
--------------------------------------------------------------------------------
[2022-12-12 12:34:20,819] {taskinstance.py:1357} INFO - Starting attempt 1 of 1
[2022-12-12 12:34:20,819] {taskinstance.py:1358} INFO - 
--------------------------------------------------------------------------------
[2022-12-12 12:34:20,878] {taskinstance.py:1377} INFO - Executing <Task(PostgresOperator): create_table> on 2022-11-28 18:40:00+00:00
[2022-12-12 12:34:20,890] {standard_task_runner.py:52} INFO - Started process 547 to run task
[2022-12-12 12:34:20,930] {standard_task_runner.py:79} INFO - Running: ['airflow', 'tasks', 'run', 'prepare_data', 'create_table', 'scheduled__2022-11-28T18:40:00+00:00', '--job-id', '128', '--raw', '--subdir', 'DAGS_FOLDER/prepare_data.py', '--cfg-path', '/tmp/tmpcxg7wb0q', '--error-file', '/tmp/tmplofhkqzg']
[2022-12-12 12:34:20,944] {standard_task_runner.py:80} INFO - Job 128: Subtask create_table
[2022-12-12 12:34:21,175] {task_command.py:369} INFO - Running <TaskInstance: prepare_data.create_table scheduled__2022-11-28T18:40:00+00:00 [running]> on host b778137d8ea6
[2022-12-12 12:34:21,443] {taskinstance.py:1571} INFO - Exporting the following env vars:
AIRFLOW_CTX_DAG_OWNER=airflow
AIRFLOW_CTX_DAG_ID=prepare_data
AIRFLOW_CTX_TASK_ID=create_table
AIRFLOW_CTX_EXECUTION_DATE=2022-11-28T18:40:00+00:00
AIRFLOW_CTX_TRY_NUMBER=1
AIRFLOW_CTX_DAG_RUN_ID=scheduled__2022-11-28T18:40:00+00:00
[2022-12-12 12:34:21,489] {taskinstance.py:1889} ERROR - Task failed with exception
Traceback (most recent call last):
  File "/home/airflow/.local/lib/python3.7/site-packages/airflow/providers/postgres/operators/postgres.py", line 92, in execute
    self.hook.run(self.sql, self.autocommit, parameters=self.parameters)
  File "/home/airflow/.local/lib/python3.7/site-packages/airflow/hooks/dbapi.py", line 181, in run
    with closing(self.get_conn()) as conn:
  File "/home/airflow/.local/lib/python3.7/site-packages/airflow/providers/postgres/hooks/postgres.py", line 86, in get_conn
    conn = deepcopy(self.connection or self.get_connection(conn_id))
  File "/home/airflow/.local/lib/python3.7/site-packages/airflow/hooks/base.py", line 67, in get_connection
    conn = Connection.get_connection_from_secrets(conn_id)
  File "/home/airflow/.local/lib/python3.7/site-packages/airflow/models/connection.py", line 430, in get_connection_from_secrets
    raise AirflowNotFoundException(f"The conn_id `{conn_id}` isn't defined")
airflow.exceptions.AirflowNotFoundException: The conn_id `postgres_default` isn't defined
[2022-12-12 12:34:21,502] {taskinstance.py:1400} INFO - Marking task as FAILED. dag_id=prepare_data, task_id=create_table, execution_date=20221128T184000, start_date=20221212T123420, end_date=20221212T123421
[2022-12-12 12:34:21,645] {standard_task_runner.py:97} ERROR - Failed to execute job 128 for task create_table (The conn_id `postgres_default` isn't defined; 547)
[2022-12-12 12:34:21,704] {local_task_job.py:156} INFO - Task exited with return code 1
[2022-12-12 12:34:22,397] {local_task_job.py:273} INFO - 0 downstream tasks scheduled from follow-on schedule check
