[2022-12-03 14:53:35,605] {taskinstance.py:1159} INFO - Dependencies all met for <TaskInstance: prepare_data.create_table scheduled__2022-11-28T18:26:00+00:00 [queued]>
[2022-12-03 14:53:36,566] {taskinstance.py:1159} INFO - Dependencies all met for <TaskInstance: prepare_data.create_table scheduled__2022-11-28T18:26:00+00:00 [queued]>
[2022-12-03 14:53:36,566] {taskinstance.py:1356} INFO - 
--------------------------------------------------------------------------------
[2022-12-03 14:53:36,566] {taskinstance.py:1357} INFO - Starting attempt 1 of 1
[2022-12-03 14:53:36,585] {taskinstance.py:1358} INFO - 
--------------------------------------------------------------------------------
[2022-12-03 14:53:37,979] {taskinstance.py:1377} INFO - Executing <Task(PostgresOperator): create_table> on 2022-11-28 18:26:00+00:00
[2022-12-03 14:53:38,200] {standard_task_runner.py:52} INFO - Started process 615 to run task
[2022-12-03 14:53:38,583] {standard_task_runner.py:79} INFO - Running: ['airflow', 'tasks', 'run', 'prepare_data', 'create_table', 'scheduled__2022-11-28T18:26:00+00:00', '--job-id', '142', '--raw', '--subdir', 'DAGS_FOLDER/prepare_data.py', '--cfg-path', '/tmp/tmp93kalgf4', '--error-file', '/tmp/tmppq_k3hsx']
[2022-12-03 14:53:38,642] {standard_task_runner.py:80} INFO - Job 142: Subtask create_table
[2022-12-03 14:53:41,602] {task_command.py:369} INFO - Running <TaskInstance: prepare_data.create_table scheduled__2022-11-28T18:26:00+00:00 [running]> on host b41792e8e843
[2022-12-03 14:53:46,975] {taskinstance.py:1571} INFO - Exporting the following env vars:
AIRFLOW_CTX_DAG_OWNER=airflow
AIRFLOW_CTX_DAG_ID=prepare_data
AIRFLOW_CTX_TASK_ID=create_table
AIRFLOW_CTX_EXECUTION_DATE=2022-11-28T18:26:00+00:00
AIRFLOW_CTX_TRY_NUMBER=1
AIRFLOW_CTX_DAG_RUN_ID=scheduled__2022-11-28T18:26:00+00:00
[2022-12-03 14:53:47,694] {base.py:68} INFO - Using connection ID 'postgres_default' for task execution.
[2022-12-03 14:53:47,878] {dbapi.py:208} INFO - Running statement: CREATE TABLE IF NOT EXISTS prepared_data (
	id SERIAL,
	sensor_id BIGINT,
	longitude FLOAT,
	latitude FLOAT,
	controller_id BIGINT,
	datetime TIMESTAMP WITH TIME ZONE,
	temperature INTEGER
);, parameters: None
[2022-12-03 14:53:47,905] {postgres.py:94} INFO - NOTICE:  relation "prepared_data" already exists, skipping

[2022-12-03 14:53:48,571] {taskinstance.py:1400} INFO - Marking task as SUCCESS. dag_id=prepare_data, task_id=create_table, execution_date=20221128T182600, start_date=20221203T145335, end_date=20221203T145348
[2022-12-03 14:53:49,388] {local_task_job.py:156} INFO - Task exited with return code 0
[2022-12-03 14:53:53,270] {local_task_job.py:273} INFO - 0 downstream tasks scheduled from follow-on schedule check
[2022-12-12 12:33:58,123] {taskinstance.py:1159} INFO - Dependencies all met for <TaskInstance: prepare_data.create_table scheduled__2022-11-28T18:26:00+00:00 [queued]>
[2022-12-12 12:33:58,232] {taskinstance.py:1159} INFO - Dependencies all met for <TaskInstance: prepare_data.create_table scheduled__2022-11-28T18:26:00+00:00 [queued]>
[2022-12-12 12:33:58,233] {taskinstance.py:1356} INFO - 
--------------------------------------------------------------------------------
[2022-12-12 12:33:58,233] {taskinstance.py:1357} INFO - Starting attempt 1 of 1
[2022-12-12 12:33:58,233] {taskinstance.py:1358} INFO - 
--------------------------------------------------------------------------------
[2022-12-12 12:33:58,495] {taskinstance.py:1377} INFO - Executing <Task(PostgresOperator): create_table> on 2022-11-28 18:26:00+00:00
[2022-12-12 12:33:58,585] {standard_task_runner.py:52} INFO - Started process 516 to run task
[2022-12-12 12:33:58,724] {standard_task_runner.py:79} INFO - Running: ['airflow', 'tasks', 'run', 'prepare_data', 'create_table', 'scheduled__2022-11-28T18:26:00+00:00', '--job-id', '114', '--raw', '--subdir', 'DAGS_FOLDER/prepare_data.py', '--cfg-path', '/tmp/tmp3mm67ecb', '--error-file', '/tmp/tmpw9vz05ik']
[2022-12-12 12:33:58,726] {standard_task_runner.py:80} INFO - Job 114: Subtask create_table
[2022-12-12 12:33:59,413] {task_command.py:369} INFO - Running <TaskInstance: prepare_data.create_table scheduled__2022-11-28T18:26:00+00:00 [running]> on host b778137d8ea6
[2022-12-12 12:34:00,706] {taskinstance.py:1571} INFO - Exporting the following env vars:
AIRFLOW_CTX_DAG_OWNER=airflow
AIRFLOW_CTX_DAG_ID=prepare_data
AIRFLOW_CTX_TASK_ID=create_table
AIRFLOW_CTX_EXECUTION_DATE=2022-11-28T18:26:00+00:00
AIRFLOW_CTX_TRY_NUMBER=1
AIRFLOW_CTX_DAG_RUN_ID=scheduled__2022-11-28T18:26:00+00:00
[2022-12-12 12:34:01,041] {taskinstance.py:1889} ERROR - Task failed with exception
Traceback (most recent call last):
  File "/home/airflow/.local/lib/python3.7/site-packages/airflow/providers/postgres/operators/postgres.py", line 92, in execute
    self.hook.run(self.sql, self.autocommit, parameters=self.parameters)
  File "/home/airflow/.local/lib/python3.7/site-packages/airflow/hooks/dbapi.py", line 181, in run
    with closing(self.get_conn()) as conn:
  File "/home/airflow/.local/lib/python3.7/site-packages/airflow/providers/postgres/hooks/postgres.py", line 86, in get_conn
    conn = deepcopy(self.connection or self.get_connection(conn_id))
  File "/home/airflow/.local/lib/python3.7/site-packages/airflow/hooks/base.py", line 67, in get_connection
    conn = Connection.get_connection_from_secrets(conn_id)
  File "/home/airflow/.local/lib/python3.7/site-packages/airflow/models/connection.py", line 430, in get_connection_from_secrets
    raise AirflowNotFoundException(f"The conn_id `{conn_id}` isn't defined")
airflow.exceptions.AirflowNotFoundException: The conn_id `postgres_default` isn't defined
[2022-12-12 12:34:01,124] {taskinstance.py:1400} INFO - Marking task as FAILED. dag_id=prepare_data, task_id=create_table, execution_date=20221128T182600, start_date=20221212T123358, end_date=20221212T123401
[2022-12-12 12:34:01,277] {standard_task_runner.py:97} ERROR - Failed to execute job 114 for task create_table (The conn_id `postgres_default` isn't defined; 516)
[2022-12-12 12:34:01,327] {local_task_job.py:156} INFO - Task exited with return code 1
[2022-12-12 12:34:02,515] {local_task_job.py:273} INFO - 0 downstream tasks scheduled from follow-on schedule check
