[2022-12-03 15:06:07,039] {taskinstance.py:1159} INFO - Dependencies all met for <TaskInstance: prepare_data.create_table scheduled__2022-11-28T19:26:00+00:00 [queued]>
[2022-12-03 15:06:08,210] {taskinstance.py:1159} INFO - Dependencies all met for <TaskInstance: prepare_data.create_table scheduled__2022-11-28T19:26:00+00:00 [queued]>
[2022-12-03 15:06:08,210] {taskinstance.py:1356} INFO - 
--------------------------------------------------------------------------------
[2022-12-03 15:06:08,211] {taskinstance.py:1357} INFO - Starting attempt 1 of 1
[2022-12-03 15:06:08,211] {taskinstance.py:1358} INFO - 
--------------------------------------------------------------------------------
[2022-12-03 15:06:09,274] {taskinstance.py:1377} INFO - Executing <Task(PostgresOperator): create_table> on 2022-11-28 19:26:00+00:00
[2022-12-03 15:06:09,692] {standard_task_runner.py:52} INFO - Started process 1064 to run task
[2022-12-03 15:06:10,151] {standard_task_runner.py:79} INFO - Running: ['airflow', 'tasks', 'run', 'prepare_data', 'create_table', 'scheduled__2022-11-28T19:26:00+00:00', '--job-id', '317', '--raw', '--subdir', 'DAGS_FOLDER/prepare_data.py', '--cfg-path', '/tmp/tmpbi128uhd', '--error-file', '/tmp/tmp8xzw9p9b']
[2022-12-03 15:06:10,260] {standard_task_runner.py:80} INFO - Job 317: Subtask create_table
[2022-12-03 15:06:14,385] {task_command.py:369} INFO - Running <TaskInstance: prepare_data.create_table scheduled__2022-11-28T19:26:00+00:00 [running]> on host b41792e8e843
[2022-12-03 15:06:21,334] {taskinstance.py:1571} INFO - Exporting the following env vars:
AIRFLOW_CTX_DAG_OWNER=airflow
AIRFLOW_CTX_DAG_ID=prepare_data
AIRFLOW_CTX_TASK_ID=create_table
AIRFLOW_CTX_EXECUTION_DATE=2022-11-28T19:26:00+00:00
AIRFLOW_CTX_TRY_NUMBER=1
AIRFLOW_CTX_DAG_RUN_ID=scheduled__2022-11-28T19:26:00+00:00
[2022-12-03 15:06:21,804] {base.py:68} INFO - Using connection ID 'postgres_default' for task execution.
[2022-12-03 15:06:21,875] {dbapi.py:208} INFO - Running statement: CREATE TABLE IF NOT EXISTS prepared_data (
	id SERIAL,
	sensor_id BIGINT,
	longitude FLOAT,
	latitude FLOAT,
	controller_id BIGINT,
	datetime TIMESTAMP WITH TIME ZONE,
	temperature INTEGER
);, parameters: None
[2022-12-03 15:06:21,890] {postgres.py:94} INFO - NOTICE:  relation "prepared_data" already exists, skipping

[2022-12-03 15:06:24,148] {taskinstance.py:1400} INFO - Marking task as SUCCESS. dag_id=prepare_data, task_id=create_table, execution_date=20221128T192600, start_date=20221203T150607, end_date=20221203T150624
[2022-12-03 15:06:25,040] {local_task_job.py:156} INFO - Task exited with return code 0
[2022-12-03 15:06:26,213] {local_task_job.py:273} INFO - 1 downstream tasks scheduled from follow-on schedule check
[2022-12-12 12:36:00,318] {taskinstance.py:1159} INFO - Dependencies all met for <TaskInstance: prepare_data.create_table scheduled__2022-11-28T19:26:00+00:00 [queued]>
[2022-12-12 12:36:00,347] {taskinstance.py:1159} INFO - Dependencies all met for <TaskInstance: prepare_data.create_table scheduled__2022-11-28T19:26:00+00:00 [queued]>
[2022-12-12 12:36:00,348] {taskinstance.py:1356} INFO - 
--------------------------------------------------------------------------------
[2022-12-12 12:36:00,348] {taskinstance.py:1357} INFO - Starting attempt 1 of 1
[2022-12-12 12:36:00,348] {taskinstance.py:1358} INFO - 
--------------------------------------------------------------------------------
[2022-12-12 12:36:00,405] {taskinstance.py:1377} INFO - Executing <Task(PostgresOperator): create_table> on 2022-11-28 19:26:00+00:00
[2022-12-12 12:36:00,413] {standard_task_runner.py:52} INFO - Started process 655 to run task
[2022-12-12 12:36:00,422] {standard_task_runner.py:79} INFO - Running: ['airflow', 'tasks', 'run', 'prepare_data', 'create_table', 'scheduled__2022-11-28T19:26:00+00:00', '--job-id', '174', '--raw', '--subdir', 'DAGS_FOLDER/prepare_data.py', '--cfg-path', '/tmp/tmp2v_mczpg', '--error-file', '/tmp/tmpg3f5j394']
[2022-12-12 12:36:00,432] {standard_task_runner.py:80} INFO - Job 174: Subtask create_table
[2022-12-12 12:36:00,637] {task_command.py:369} INFO - Running <TaskInstance: prepare_data.create_table scheduled__2022-11-28T19:26:00+00:00 [running]> on host b778137d8ea6
[2022-12-12 12:36:00,896] {taskinstance.py:1571} INFO - Exporting the following env vars:
AIRFLOW_CTX_DAG_OWNER=airflow
AIRFLOW_CTX_DAG_ID=prepare_data
AIRFLOW_CTX_TASK_ID=create_table
AIRFLOW_CTX_EXECUTION_DATE=2022-11-28T19:26:00+00:00
AIRFLOW_CTX_TRY_NUMBER=1
AIRFLOW_CTX_DAG_RUN_ID=scheduled__2022-11-28T19:26:00+00:00
[2022-12-12 12:36:00,967] {taskinstance.py:1889} ERROR - Task failed with exception
Traceback (most recent call last):
  File "/home/airflow/.local/lib/python3.7/site-packages/airflow/providers/postgres/operators/postgres.py", line 92, in execute
    self.hook.run(self.sql, self.autocommit, parameters=self.parameters)
  File "/home/airflow/.local/lib/python3.7/site-packages/airflow/hooks/dbapi.py", line 181, in run
    with closing(self.get_conn()) as conn:
  File "/home/airflow/.local/lib/python3.7/site-packages/airflow/providers/postgres/hooks/postgres.py", line 86, in get_conn
    conn = deepcopy(self.connection or self.get_connection(conn_id))
  File "/home/airflow/.local/lib/python3.7/site-packages/airflow/hooks/base.py", line 67, in get_connection
    conn = Connection.get_connection_from_secrets(conn_id)
  File "/home/airflow/.local/lib/python3.7/site-packages/airflow/models/connection.py", line 430, in get_connection_from_secrets
    raise AirflowNotFoundException(f"The conn_id `{conn_id}` isn't defined")
airflow.exceptions.AirflowNotFoundException: The conn_id `postgres_default` isn't defined
[2022-12-12 12:36:00,981] {taskinstance.py:1400} INFO - Marking task as FAILED. dag_id=prepare_data, task_id=create_table, execution_date=20221128T192600, start_date=20221212T123600, end_date=20221212T123600
[2022-12-12 12:36:01,014] {standard_task_runner.py:97} ERROR - Failed to execute job 174 for task create_table (The conn_id `postgres_default` isn't defined; 655)
[2022-12-12 12:36:01,056] {local_task_job.py:156} INFO - Task exited with return code 1
[2022-12-12 12:36:01,265] {local_task_job.py:273} INFO - 0 downstream tasks scheduled from follow-on schedule check
