[2022-12-03 14:44:33,733] {taskinstance.py:1159} INFO - Dependencies all met for <TaskInstance: prepare_data.create_table scheduled__2022-11-28T16:55:00+00:00 [queued]>
[2022-12-03 14:44:34,062] {taskinstance.py:1159} INFO - Dependencies all met for <TaskInstance: prepare_data.create_table scheduled__2022-11-28T16:55:00+00:00 [queued]>
[2022-12-03 14:44:34,062] {taskinstance.py:1356} INFO - 
--------------------------------------------------------------------------------
[2022-12-03 14:44:34,062] {taskinstance.py:1357} INFO - Starting attempt 1 of 1
[2022-12-03 14:44:34,062] {taskinstance.py:1358} INFO - 
--------------------------------------------------------------------------------
[2022-12-03 14:44:34,494] {taskinstance.py:1377} INFO - Executing <Task(PostgresOperator): create_table> on 2022-11-28 16:55:00+00:00
[2022-12-03 14:44:34,598] {standard_task_runner.py:52} INFO - Started process 304 to run task
[2022-12-03 14:44:34,780] {standard_task_runner.py:79} INFO - Running: ['airflow', 'tasks', 'run', 'prepare_data', 'create_table', 'scheduled__2022-11-28T16:55:00+00:00', '--job-id', '23', '--raw', '--subdir', 'DAGS_FOLDER/prepare_data.py', '--cfg-path', '/tmp/tmpflahe04d', '--error-file', '/tmp/tmprtckt7jm']
[2022-12-03 14:44:34,834] {standard_task_runner.py:80} INFO - Job 23: Subtask create_table
[2022-12-03 14:44:36,664] {task_command.py:369} INFO - Running <TaskInstance: prepare_data.create_table scheduled__2022-11-28T16:55:00+00:00 [running]> on host b41792e8e843
[2022-12-03 14:44:39,195] {taskinstance.py:1571} INFO - Exporting the following env vars:
AIRFLOW_CTX_DAG_OWNER=airflow
AIRFLOW_CTX_DAG_ID=prepare_data
AIRFLOW_CTX_TASK_ID=create_table
AIRFLOW_CTX_EXECUTION_DATE=2022-11-28T16:55:00+00:00
AIRFLOW_CTX_TRY_NUMBER=1
AIRFLOW_CTX_DAG_RUN_ID=scheduled__2022-11-28T16:55:00+00:00
[2022-12-03 14:44:40,800] {taskinstance.py:1889} ERROR - Task failed with exception
Traceback (most recent call last):
  File "/home/airflow/.local/lib/python3.7/site-packages/airflow/providers/postgres/operators/postgres.py", line 92, in execute
    self.hook.run(self.sql, self.autocommit, parameters=self.parameters)
  File "/home/airflow/.local/lib/python3.7/site-packages/airflow/hooks/dbapi.py", line 181, in run
    with closing(self.get_conn()) as conn:
  File "/home/airflow/.local/lib/python3.7/site-packages/airflow/providers/postgres/hooks/postgres.py", line 86, in get_conn
    conn = deepcopy(self.connection or self.get_connection(conn_id))
  File "/home/airflow/.local/lib/python3.7/site-packages/airflow/hooks/base.py", line 67, in get_connection
    conn = Connection.get_connection_from_secrets(conn_id)
  File "/home/airflow/.local/lib/python3.7/site-packages/airflow/models/connection.py", line 430, in get_connection_from_secrets
    raise AirflowNotFoundException(f"The conn_id `{conn_id}` isn't defined")
airflow.exceptions.AirflowNotFoundException: The conn_id `postgres_default` isn't defined
[2022-12-03 14:44:40,839] {taskinstance.py:1400} INFO - Marking task as FAILED. dag_id=prepare_data, task_id=create_table, execution_date=20221128T165500, start_date=20221203T144433, end_date=20221203T144440
[2022-12-03 14:44:41,004] {standard_task_runner.py:97} ERROR - Failed to execute job 23 for task create_table (The conn_id `postgres_default` isn't defined; 304)
[2022-12-03 14:44:41,064] {local_task_job.py:156} INFO - Task exited with return code 1
[2022-12-03 14:44:42,182] {local_task_job.py:273} INFO - 0 downstream tasks scheduled from follow-on schedule check
[2022-12-12 12:30:02,597] {taskinstance.py:1159} INFO - Dependencies all met for <TaskInstance: prepare_data.create_table scheduled__2022-11-28T16:55:00+00:00 [queued]>
[2022-12-12 12:30:03,619] {taskinstance.py:1159} INFO - Dependencies all met for <TaskInstance: prepare_data.create_table scheduled__2022-11-28T16:55:00+00:00 [queued]>
[2022-12-12 12:30:03,620] {taskinstance.py:1356} INFO - 
--------------------------------------------------------------------------------
[2022-12-12 12:30:03,620] {taskinstance.py:1357} INFO - Starting attempt 1 of 1
[2022-12-12 12:30:03,620] {taskinstance.py:1358} INFO - 
--------------------------------------------------------------------------------
[2022-12-12 12:30:04,995] {taskinstance.py:1377} INFO - Executing <Task(PostgresOperator): create_table> on 2022-11-28 16:55:00+00:00
[2022-12-12 12:30:05,248] {standard_task_runner.py:52} INFO - Started process 298 to run task
[2022-12-12 12:30:05,434] {standard_task_runner.py:79} INFO - Running: ['airflow', 'tasks', 'run', 'prepare_data', 'create_table', 'scheduled__2022-11-28T16:55:00+00:00', '--job-id', '23', '--raw', '--subdir', 'DAGS_FOLDER/prepare_data.py', '--cfg-path', '/tmp/tmpvv6mhnw_', '--error-file', '/tmp/tmpeft9ucfv']
[2022-12-12 12:30:05,468] {standard_task_runner.py:80} INFO - Job 23: Subtask create_table
[2022-12-12 12:30:08,451] {task_command.py:369} INFO - Running <TaskInstance: prepare_data.create_table scheduled__2022-11-28T16:55:00+00:00 [running]> on host b778137d8ea6
[2022-12-12 12:30:12,234] {taskinstance.py:1571} INFO - Exporting the following env vars:
AIRFLOW_CTX_DAG_OWNER=airflow
AIRFLOW_CTX_DAG_ID=prepare_data
AIRFLOW_CTX_TASK_ID=create_table
AIRFLOW_CTX_EXECUTION_DATE=2022-11-28T16:55:00+00:00
AIRFLOW_CTX_TRY_NUMBER=1
AIRFLOW_CTX_DAG_RUN_ID=scheduled__2022-11-28T16:55:00+00:00
[2022-12-12 12:30:13,428] {taskinstance.py:1889} ERROR - Task failed with exception
Traceback (most recent call last):
  File "/home/airflow/.local/lib/python3.7/site-packages/airflow/providers/postgres/operators/postgres.py", line 92, in execute
    self.hook.run(self.sql, self.autocommit, parameters=self.parameters)
  File "/home/airflow/.local/lib/python3.7/site-packages/airflow/hooks/dbapi.py", line 181, in run
    with closing(self.get_conn()) as conn:
  File "/home/airflow/.local/lib/python3.7/site-packages/airflow/providers/postgres/hooks/postgres.py", line 86, in get_conn
    conn = deepcopy(self.connection or self.get_connection(conn_id))
  File "/home/airflow/.local/lib/python3.7/site-packages/airflow/hooks/base.py", line 67, in get_connection
    conn = Connection.get_connection_from_secrets(conn_id)
  File "/home/airflow/.local/lib/python3.7/site-packages/airflow/models/connection.py", line 430, in get_connection_from_secrets
    raise AirflowNotFoundException(f"The conn_id `{conn_id}` isn't defined")
airflow.exceptions.AirflowNotFoundException: The conn_id `postgres_default` isn't defined
[2022-12-12 12:30:13,557] {taskinstance.py:1400} INFO - Marking task as FAILED. dag_id=prepare_data, task_id=create_table, execution_date=20221128T165500, start_date=20221212T123002, end_date=20221212T123013
[2022-12-12 12:30:14,320] {standard_task_runner.py:97} ERROR - Failed to execute job 23 for task create_table (The conn_id `postgres_default` isn't defined; 298)
[2022-12-12 12:30:14,531] {local_task_job.py:156} INFO - Task exited with return code 1
[2022-12-12 12:30:16,711] {local_task_job.py:273} INFO - 0 downstream tasks scheduled from follow-on schedule check
[2022-12-12 15:14:05,422] {taskinstance.py:1159} INFO - Dependencies all met for <TaskInstance: prepare_data.create_table scheduled__2022-11-28T16:55:00+00:00 [queued]>
[2022-12-12 15:14:06,030] {taskinstance.py:1159} INFO - Dependencies all met for <TaskInstance: prepare_data.create_table scheduled__2022-11-28T16:55:00+00:00 [queued]>
[2022-12-12 15:14:06,031] {taskinstance.py:1356} INFO - 
--------------------------------------------------------------------------------
[2022-12-12 15:14:06,031] {taskinstance.py:1357} INFO - Starting attempt 1 of 1
[2022-12-12 15:14:06,061] {taskinstance.py:1358} INFO - 
--------------------------------------------------------------------------------
[2022-12-12 15:14:06,996] {taskinstance.py:1377} INFO - Executing <Task(PostgresOperator): create_table> on 2022-11-28 16:55:00+00:00
[2022-12-12 15:14:07,191] {standard_task_runner.py:52} INFO - Started process 333 to run task
[2022-12-12 15:14:07,319] {standard_task_runner.py:79} INFO - Running: ['airflow', 'tasks', 'run', 'prepare_data', 'create_table', 'scheduled__2022-11-28T16:55:00+00:00', '--job-id', '23', '--raw', '--subdir', 'DAGS_FOLDER/prepare_data.py', '--cfg-path', '/tmp/tmpyunfkyh9', '--error-file', '/tmp/tmpd_sz4h21']
[2022-12-12 15:14:07,359] {standard_task_runner.py:80} INFO - Job 23: Subtask create_table
[2022-12-12 15:14:10,933] {task_command.py:369} INFO - Running <TaskInstance: prepare_data.create_table scheduled__2022-11-28T16:55:00+00:00 [running]> on host d4eb34144d92
[2022-12-12 15:14:17,091] {taskinstance.py:1571} INFO - Exporting the following env vars:
AIRFLOW_CTX_DAG_OWNER=airflow
AIRFLOW_CTX_DAG_ID=prepare_data
AIRFLOW_CTX_TASK_ID=create_table
AIRFLOW_CTX_EXECUTION_DATE=2022-11-28T16:55:00+00:00
AIRFLOW_CTX_TRY_NUMBER=1
AIRFLOW_CTX_DAG_RUN_ID=scheduled__2022-11-28T16:55:00+00:00
[2022-12-12 15:14:19,963] {taskinstance.py:1889} ERROR - Task failed with exception
Traceback (most recent call last):
  File "/home/airflow/.local/lib/python3.7/site-packages/airflow/providers/postgres/operators/postgres.py", line 92, in execute
    self.hook.run(self.sql, self.autocommit, parameters=self.parameters)
  File "/home/airflow/.local/lib/python3.7/site-packages/airflow/hooks/dbapi.py", line 181, in run
    with closing(self.get_conn()) as conn:
  File "/home/airflow/.local/lib/python3.7/site-packages/airflow/providers/postgres/hooks/postgres.py", line 86, in get_conn
    conn = deepcopy(self.connection or self.get_connection(conn_id))
  File "/home/airflow/.local/lib/python3.7/site-packages/airflow/hooks/base.py", line 67, in get_connection
    conn = Connection.get_connection_from_secrets(conn_id)
  File "/home/airflow/.local/lib/python3.7/site-packages/airflow/models/connection.py", line 430, in get_connection_from_secrets
    raise AirflowNotFoundException(f"The conn_id `{conn_id}` isn't defined")
airflow.exceptions.AirflowNotFoundException: The conn_id `postgres_default` isn't defined
[2022-12-12 15:14:20,295] {taskinstance.py:1400} INFO - Marking task as FAILED. dag_id=prepare_data, task_id=create_table, execution_date=20221128T165500, start_date=20221212T151405, end_date=20221212T151420
[2022-12-12 15:14:21,108] {standard_task_runner.py:97} ERROR - Failed to execute job 23 for task create_table (The conn_id `postgres_default` isn't defined; 333)
[2022-12-12 15:14:21,381] {local_task_job.py:156} INFO - Task exited with return code 1
[2022-12-12 15:14:23,017] {local_task_job.py:273} INFO - 0 downstream tasks scheduled from follow-on schedule check
