[2022-12-03 14:47:06,830] {taskinstance.py:1159} INFO - Dependencies all met for <TaskInstance: prepare_data.create_table scheduled__2022-11-28T17:42:00+00:00 [queued]>
[2022-12-03 14:47:06,891] {taskinstance.py:1159} INFO - Dependencies all met for <TaskInstance: prepare_data.create_table scheduled__2022-11-28T17:42:00+00:00 [queued]>
[2022-12-03 14:47:06,892] {taskinstance.py:1356} INFO - 
--------------------------------------------------------------------------------
[2022-12-03 14:47:06,892] {taskinstance.py:1357} INFO - Starting attempt 1 of 1
[2022-12-03 14:47:06,892] {taskinstance.py:1358} INFO - 
--------------------------------------------------------------------------------
[2022-12-03 14:47:06,991] {taskinstance.py:1377} INFO - Executing <Task(PostgresOperator): create_table> on 2022-11-28 17:42:00+00:00
[2022-12-03 14:47:07,015] {standard_task_runner.py:52} INFO - Started process 422 to run task
[2022-12-03 14:47:07,055] {standard_task_runner.py:79} INFO - Running: ['airflow', 'tasks', 'run', 'prepare_data', 'create_table', 'scheduled__2022-11-28T17:42:00+00:00', '--job-id', '70', '--raw', '--subdir', 'DAGS_FOLDER/prepare_data.py', '--cfg-path', '/tmp/tmpmtrvmap1', '--error-file', '/tmp/tmp4gmd45k3']
[2022-12-03 14:47:07,060] {standard_task_runner.py:80} INFO - Job 70: Subtask create_table
[2022-12-03 14:47:07,493] {task_command.py:369} INFO - Running <TaskInstance: prepare_data.create_table scheduled__2022-11-28T17:42:00+00:00 [running]> on host b41792e8e843
[2022-12-03 14:47:09,079] {taskinstance.py:1571} INFO - Exporting the following env vars:
AIRFLOW_CTX_DAG_OWNER=airflow
AIRFLOW_CTX_DAG_ID=prepare_data
AIRFLOW_CTX_TASK_ID=create_table
AIRFLOW_CTX_EXECUTION_DATE=2022-11-28T17:42:00+00:00
AIRFLOW_CTX_TRY_NUMBER=1
AIRFLOW_CTX_DAG_RUN_ID=scheduled__2022-11-28T17:42:00+00:00
[2022-12-03 14:47:10,118] {taskinstance.py:1889} ERROR - Task failed with exception
Traceback (most recent call last):
  File "/home/airflow/.local/lib/python3.7/site-packages/airflow/providers/postgres/operators/postgres.py", line 92, in execute
    self.hook.run(self.sql, self.autocommit, parameters=self.parameters)
  File "/home/airflow/.local/lib/python3.7/site-packages/airflow/hooks/dbapi.py", line 181, in run
    with closing(self.get_conn()) as conn:
  File "/home/airflow/.local/lib/python3.7/site-packages/airflow/providers/postgres/hooks/postgres.py", line 86, in get_conn
    conn = deepcopy(self.connection or self.get_connection(conn_id))
  File "/home/airflow/.local/lib/python3.7/site-packages/airflow/hooks/base.py", line 67, in get_connection
    conn = Connection.get_connection_from_secrets(conn_id)
  File "/home/airflow/.local/lib/python3.7/site-packages/airflow/models/connection.py", line 430, in get_connection_from_secrets
    raise AirflowNotFoundException(f"The conn_id `{conn_id}` isn't defined")
airflow.exceptions.AirflowNotFoundException: The conn_id `postgres_default` isn't defined
[2022-12-03 14:47:10,555] {taskinstance.py:1400} INFO - Marking task as FAILED. dag_id=prepare_data, task_id=create_table, execution_date=20221128T174200, start_date=20221203T144706, end_date=20221203T144710
[2022-12-03 14:47:11,134] {standard_task_runner.py:97} ERROR - Failed to execute job 70 for task create_table (The conn_id `postgres_default` isn't defined; 422)
[2022-12-03 14:47:11,308] {local_task_job.py:156} INFO - Task exited with return code 1
[2022-12-03 14:47:14,821] {local_task_job.py:273} INFO - 0 downstream tasks scheduled from follow-on schedule check
[2022-12-12 12:32:37,460] {taskinstance.py:1159} INFO - Dependencies all met for <TaskInstance: prepare_data.create_table scheduled__2022-11-28T17:42:00+00:00 [queued]>
[2022-12-12 12:32:37,611] {taskinstance.py:1159} INFO - Dependencies all met for <TaskInstance: prepare_data.create_table scheduled__2022-11-28T17:42:00+00:00 [queued]>
[2022-12-12 12:32:37,611] {taskinstance.py:1356} INFO - 
--------------------------------------------------------------------------------
[2022-12-12 12:32:37,611] {taskinstance.py:1357} INFO - Starting attempt 1 of 1
[2022-12-12 12:32:37,611] {taskinstance.py:1358} INFO - 
--------------------------------------------------------------------------------
[2022-12-12 12:32:37,785] {taskinstance.py:1377} INFO - Executing <Task(PostgresOperator): create_table> on 2022-11-28 17:42:00+00:00
[2022-12-12 12:32:37,796] {standard_task_runner.py:52} INFO - Started process 417 to run task
[2022-12-12 12:32:37,829] {standard_task_runner.py:79} INFO - Running: ['airflow', 'tasks', 'run', 'prepare_data', 'create_table', 'scheduled__2022-11-28T17:42:00+00:00', '--job-id', '70', '--raw', '--subdir', 'DAGS_FOLDER/prepare_data.py', '--cfg-path', '/tmp/tmpms80kooa', '--error-file', '/tmp/tmph1uu_unu']
[2022-12-12 12:32:37,830] {standard_task_runner.py:80} INFO - Job 70: Subtask create_table
[2022-12-12 12:32:38,312] {task_command.py:369} INFO - Running <TaskInstance: prepare_data.create_table scheduled__2022-11-28T17:42:00+00:00 [running]> on host b778137d8ea6
[2022-12-12 12:32:38,823] {taskinstance.py:1571} INFO - Exporting the following env vars:
AIRFLOW_CTX_DAG_OWNER=airflow
AIRFLOW_CTX_DAG_ID=prepare_data
AIRFLOW_CTX_TASK_ID=create_table
AIRFLOW_CTX_EXECUTION_DATE=2022-11-28T17:42:00+00:00
AIRFLOW_CTX_TRY_NUMBER=1
AIRFLOW_CTX_DAG_RUN_ID=scheduled__2022-11-28T17:42:00+00:00
[2022-12-12 12:32:39,261] {taskinstance.py:1889} ERROR - Task failed with exception
Traceback (most recent call last):
  File "/home/airflow/.local/lib/python3.7/site-packages/airflow/providers/postgres/operators/postgres.py", line 92, in execute
    self.hook.run(self.sql, self.autocommit, parameters=self.parameters)
  File "/home/airflow/.local/lib/python3.7/site-packages/airflow/hooks/dbapi.py", line 181, in run
    with closing(self.get_conn()) as conn:
  File "/home/airflow/.local/lib/python3.7/site-packages/airflow/providers/postgres/hooks/postgres.py", line 86, in get_conn
    conn = deepcopy(self.connection or self.get_connection(conn_id))
  File "/home/airflow/.local/lib/python3.7/site-packages/airflow/hooks/base.py", line 67, in get_connection
    conn = Connection.get_connection_from_secrets(conn_id)
  File "/home/airflow/.local/lib/python3.7/site-packages/airflow/models/connection.py", line 430, in get_connection_from_secrets
    raise AirflowNotFoundException(f"The conn_id `{conn_id}` isn't defined")
airflow.exceptions.AirflowNotFoundException: The conn_id `postgres_default` isn't defined
[2022-12-12 12:32:39,290] {taskinstance.py:1400} INFO - Marking task as FAILED. dag_id=prepare_data, task_id=create_table, execution_date=20221128T174200, start_date=20221212T123237, end_date=20221212T123239
[2022-12-12 12:32:39,369] {standard_task_runner.py:97} ERROR - Failed to execute job 70 for task create_table (The conn_id `postgres_default` isn't defined; 417)
[2022-12-12 12:32:39,436] {local_task_job.py:156} INFO - Task exited with return code 1
[2022-12-12 12:32:39,721] {local_task_job.py:273} INFO - 0 downstream tasks scheduled from follow-on schedule check
