[2022-12-03 14:54:15,275] {taskinstance.py:1159} INFO - Dependencies all met for <TaskInstance: prepare_data.create_table scheduled__2022-11-28T18:27:00+00:00 [queued]>
[2022-12-03 14:54:15,558] {taskinstance.py:1159} INFO - Dependencies all met for <TaskInstance: prepare_data.create_table scheduled__2022-11-28T18:27:00+00:00 [queued]>
[2022-12-03 14:54:15,559] {taskinstance.py:1356} INFO - 
--------------------------------------------------------------------------------
[2022-12-03 14:54:15,559] {taskinstance.py:1357} INFO - Starting attempt 1 of 1
[2022-12-03 14:54:15,559] {taskinstance.py:1358} INFO - 
--------------------------------------------------------------------------------
[2022-12-03 14:54:17,670] {taskinstance.py:1377} INFO - Executing <Task(PostgresOperator): create_table> on 2022-11-28 18:27:00+00:00
[2022-12-03 14:54:17,756] {standard_task_runner.py:79} INFO - Running: ['airflow', 'tasks', 'run', 'prepare_data', 'create_table', 'scheduled__2022-11-28T18:27:00+00:00', '--job-id', '149', '--raw', '--subdir', 'DAGS_FOLDER/prepare_data.py', '--cfg-path', '/tmp/tmp2lsiywee', '--error-file', '/tmp/tmpkb7fui75']
[2022-12-03 14:54:17,773] {standard_task_runner.py:80} INFO - Job 149: Subtask create_table
[2022-12-03 14:54:17,696] {standard_task_runner.py:52} INFO - Started process 634 to run task
[2022-12-03 14:54:22,398] {task_command.py:369} INFO - Running <TaskInstance: prepare_data.create_table scheduled__2022-11-28T18:27:00+00:00 [running]> on host b41792e8e843
[2022-12-03 14:54:29,724] {taskinstance.py:1571} INFO - Exporting the following env vars:
AIRFLOW_CTX_DAG_OWNER=airflow
AIRFLOW_CTX_DAG_ID=prepare_data
AIRFLOW_CTX_TASK_ID=create_table
AIRFLOW_CTX_EXECUTION_DATE=2022-11-28T18:27:00+00:00
AIRFLOW_CTX_TRY_NUMBER=1
AIRFLOW_CTX_DAG_RUN_ID=scheduled__2022-11-28T18:27:00+00:00
[2022-12-03 14:54:30,292] {base.py:68} INFO - Using connection ID 'postgres_default' for task execution.
[2022-12-03 14:54:30,465] {dbapi.py:208} INFO - Running statement: CREATE TABLE IF NOT EXISTS prepared_data (
	id SERIAL,
	sensor_id BIGINT,
	longitude FLOAT,
	latitude FLOAT,
	controller_id BIGINT,
	datetime TIMESTAMP WITH TIME ZONE,
	temperature INTEGER
);, parameters: None
[2022-12-03 14:54:30,559] {postgres.py:94} INFO - NOTICE:  relation "prepared_data" already exists, skipping

[2022-12-03 14:54:31,310] {taskinstance.py:1400} INFO - Marking task as SUCCESS. dag_id=prepare_data, task_id=create_table, execution_date=20221128T182700, start_date=20221203T145415, end_date=20221203T145431
[2022-12-03 14:54:31,846] {local_task_job.py:156} INFO - Task exited with return code 0
[2022-12-03 14:54:34,531] {local_task_job.py:273} INFO - 1 downstream tasks scheduled from follow-on schedule check
[2022-12-12 12:33:59,257] {taskinstance.py:1159} INFO - Dependencies all met for <TaskInstance: prepare_data.create_table scheduled__2022-11-28T18:27:00+00:00 [queued]>
[2022-12-12 12:33:59,422] {taskinstance.py:1159} INFO - Dependencies all met for <TaskInstance: prepare_data.create_table scheduled__2022-11-28T18:27:00+00:00 [queued]>
[2022-12-12 12:33:59,422] {taskinstance.py:1356} INFO - 
--------------------------------------------------------------------------------
[2022-12-12 12:33:59,422] {taskinstance.py:1357} INFO - Starting attempt 1 of 1
[2022-12-12 12:33:59,422] {taskinstance.py:1358} INFO - 
--------------------------------------------------------------------------------
[2022-12-12 12:33:59,754] {taskinstance.py:1377} INFO - Executing <Task(PostgresOperator): create_table> on 2022-11-28 18:27:00+00:00
[2022-12-12 12:33:59,797] {standard_task_runner.py:52} INFO - Started process 518 to run task
[2022-12-12 12:33:59,928] {standard_task_runner.py:79} INFO - Running: ['airflow', 'tasks', 'run', 'prepare_data', 'create_table', 'scheduled__2022-11-28T18:27:00+00:00', '--job-id', '115', '--raw', '--subdir', 'DAGS_FOLDER/prepare_data.py', '--cfg-path', '/tmp/tmp09t040yw', '--error-file', '/tmp/tmp3fwfw4lh']
[2022-12-12 12:33:59,929] {standard_task_runner.py:80} INFO - Job 115: Subtask create_table
[2022-12-12 12:34:00,915] {task_command.py:369} INFO - Running <TaskInstance: prepare_data.create_table scheduled__2022-11-28T18:27:00+00:00 [running]> on host b778137d8ea6
[2022-12-12 12:34:01,980] {taskinstance.py:1571} INFO - Exporting the following env vars:
AIRFLOW_CTX_DAG_OWNER=airflow
AIRFLOW_CTX_DAG_ID=prepare_data
AIRFLOW_CTX_TASK_ID=create_table
AIRFLOW_CTX_EXECUTION_DATE=2022-11-28T18:27:00+00:00
AIRFLOW_CTX_TRY_NUMBER=1
AIRFLOW_CTX_DAG_RUN_ID=scheduled__2022-11-28T18:27:00+00:00
[2022-12-12 12:34:02,267] {taskinstance.py:1889} ERROR - Task failed with exception
Traceback (most recent call last):
  File "/home/airflow/.local/lib/python3.7/site-packages/airflow/providers/postgres/operators/postgres.py", line 92, in execute
    self.hook.run(self.sql, self.autocommit, parameters=self.parameters)
  File "/home/airflow/.local/lib/python3.7/site-packages/airflow/hooks/dbapi.py", line 181, in run
    with closing(self.get_conn()) as conn:
  File "/home/airflow/.local/lib/python3.7/site-packages/airflow/providers/postgres/hooks/postgres.py", line 86, in get_conn
    conn = deepcopy(self.connection or self.get_connection(conn_id))
  File "/home/airflow/.local/lib/python3.7/site-packages/airflow/hooks/base.py", line 67, in get_connection
    conn = Connection.get_connection_from_secrets(conn_id)
  File "/home/airflow/.local/lib/python3.7/site-packages/airflow/models/connection.py", line 430, in get_connection_from_secrets
    raise AirflowNotFoundException(f"The conn_id `{conn_id}` isn't defined")
airflow.exceptions.AirflowNotFoundException: The conn_id `postgres_default` isn't defined
[2022-12-12 12:34:02,329] {taskinstance.py:1400} INFO - Marking task as FAILED. dag_id=prepare_data, task_id=create_table, execution_date=20221128T182700, start_date=20221212T123359, end_date=20221212T123402
[2022-12-12 12:34:02,440] {standard_task_runner.py:97} ERROR - Failed to execute job 115 for task create_table (The conn_id `postgres_default` isn't defined; 518)
[2022-12-12 12:34:02,488] {local_task_job.py:156} INFO - Task exited with return code 1
[2022-12-12 12:34:03,035] {local_task_job.py:273} INFO - 0 downstream tasks scheduled from follow-on schedule check
