[2022-12-03 14:44:42,114] {taskinstance.py:1159} INFO - Dependencies all met for <TaskInstance: prepare_data.create_table scheduled__2022-11-28T16:58:00+00:00 [queued]>
[2022-12-03 14:44:42,511] {taskinstance.py:1159} INFO - Dependencies all met for <TaskInstance: prepare_data.create_table scheduled__2022-11-28T16:58:00+00:00 [queued]>
[2022-12-03 14:44:42,512] {taskinstance.py:1356} INFO - 
--------------------------------------------------------------------------------
[2022-12-03 14:44:42,512] {taskinstance.py:1357} INFO - Starting attempt 1 of 1
[2022-12-03 14:44:42,512] {taskinstance.py:1358} INFO - 
--------------------------------------------------------------------------------
[2022-12-03 14:44:42,830] {taskinstance.py:1377} INFO - Executing <Task(PostgresOperator): create_table> on 2022-11-28 16:58:00+00:00
[2022-12-03 14:44:42,870] {standard_task_runner.py:52} INFO - Started process 314 to run task
[2022-12-03 14:44:42,969] {standard_task_runner.py:79} INFO - Running: ['airflow', 'tasks', 'run', 'prepare_data', 'create_table', 'scheduled__2022-11-28T16:58:00+00:00', '--job-id', '26', '--raw', '--subdir', 'DAGS_FOLDER/prepare_data.py', '--cfg-path', '/tmp/tmp8l2_w9sj', '--error-file', '/tmp/tmpgntixioi']
[2022-12-03 14:44:43,018] {standard_task_runner.py:80} INFO - Job 26: Subtask create_table
[2022-12-03 14:44:44,575] {task_command.py:369} INFO - Running <TaskInstance: prepare_data.create_table scheduled__2022-11-28T16:58:00+00:00 [running]> on host b41792e8e843
[2022-12-03 14:44:45,991] {taskinstance.py:1571} INFO - Exporting the following env vars:
AIRFLOW_CTX_DAG_OWNER=airflow
AIRFLOW_CTX_DAG_ID=prepare_data
AIRFLOW_CTX_TASK_ID=create_table
AIRFLOW_CTX_EXECUTION_DATE=2022-11-28T16:58:00+00:00
AIRFLOW_CTX_TRY_NUMBER=1
AIRFLOW_CTX_DAG_RUN_ID=scheduled__2022-11-28T16:58:00+00:00
[2022-12-03 14:44:46,912] {taskinstance.py:1889} ERROR - Task failed with exception
Traceback (most recent call last):
  File "/home/airflow/.local/lib/python3.7/site-packages/airflow/providers/postgres/operators/postgres.py", line 92, in execute
    self.hook.run(self.sql, self.autocommit, parameters=self.parameters)
  File "/home/airflow/.local/lib/python3.7/site-packages/airflow/hooks/dbapi.py", line 181, in run
    with closing(self.get_conn()) as conn:
  File "/home/airflow/.local/lib/python3.7/site-packages/airflow/providers/postgres/hooks/postgres.py", line 86, in get_conn
    conn = deepcopy(self.connection or self.get_connection(conn_id))
  File "/home/airflow/.local/lib/python3.7/site-packages/airflow/hooks/base.py", line 67, in get_connection
    conn = Connection.get_connection_from_secrets(conn_id)
  File "/home/airflow/.local/lib/python3.7/site-packages/airflow/models/connection.py", line 430, in get_connection_from_secrets
    raise AirflowNotFoundException(f"The conn_id `{conn_id}` isn't defined")
airflow.exceptions.AirflowNotFoundException: The conn_id `postgres_default` isn't defined
[2022-12-03 14:44:47,244] {taskinstance.py:1400} INFO - Marking task as FAILED. dag_id=prepare_data, task_id=create_table, execution_date=20221128T165800, start_date=20221203T144442, end_date=20221203T144447
[2022-12-03 14:44:47,900] {standard_task_runner.py:97} ERROR - Failed to execute job 26 for task create_table (The conn_id `postgres_default` isn't defined; 314)
[2022-12-03 14:44:51,695] {local_task_job.py:156} INFO - Task exited with return code 1
[2022-12-03 14:44:54,034] {local_task_job.py:273} INFO - 0 downstream tasks scheduled from follow-on schedule check
[2022-12-12 12:30:30,766] {taskinstance.py:1159} INFO - Dependencies all met for <TaskInstance: prepare_data.create_table scheduled__2022-11-28T16:58:00+00:00 [queued]>
[2022-12-12 12:30:31,731] {taskinstance.py:1159} INFO - Dependencies all met for <TaskInstance: prepare_data.create_table scheduled__2022-11-28T16:58:00+00:00 [queued]>
[2022-12-12 12:30:31,732] {taskinstance.py:1356} INFO - 
--------------------------------------------------------------------------------
[2022-12-12 12:30:31,732] {taskinstance.py:1357} INFO - Starting attempt 1 of 1
[2022-12-12 12:30:31,732] {taskinstance.py:1358} INFO - 
--------------------------------------------------------------------------------
[2022-12-12 12:30:32,805] {taskinstance.py:1377} INFO - Executing <Task(PostgresOperator): create_table> on 2022-11-28 16:58:00+00:00
[2022-12-12 12:30:32,938] {standard_task_runner.py:52} INFO - Started process 310 to run task
[2022-12-12 12:30:33,111] {standard_task_runner.py:79} INFO - Running: ['airflow', 'tasks', 'run', 'prepare_data', 'create_table', 'scheduled__2022-11-28T16:58:00+00:00', '--job-id', '26', '--raw', '--subdir', 'DAGS_FOLDER/prepare_data.py', '--cfg-path', '/tmp/tmpwkg8qk_c', '--error-file', '/tmp/tmpsa8m8pb0']
[2022-12-12 12:30:33,155] {standard_task_runner.py:80} INFO - Job 26: Subtask create_table
[2022-12-12 12:30:36,818] {task_command.py:369} INFO - Running <TaskInstance: prepare_data.create_table scheduled__2022-11-28T16:58:00+00:00 [running]> on host b778137d8ea6
[2022-12-12 12:30:39,229] {taskinstance.py:1571} INFO - Exporting the following env vars:
AIRFLOW_CTX_DAG_OWNER=airflow
AIRFLOW_CTX_DAG_ID=prepare_data
AIRFLOW_CTX_TASK_ID=create_table
AIRFLOW_CTX_EXECUTION_DATE=2022-11-28T16:58:00+00:00
AIRFLOW_CTX_TRY_NUMBER=1
AIRFLOW_CTX_DAG_RUN_ID=scheduled__2022-11-28T16:58:00+00:00
[2022-12-12 12:30:39,825] {taskinstance.py:1889} ERROR - Task failed with exception
Traceback (most recent call last):
  File "/home/airflow/.local/lib/python3.7/site-packages/airflow/providers/postgres/operators/postgres.py", line 92, in execute
    self.hook.run(self.sql, self.autocommit, parameters=self.parameters)
  File "/home/airflow/.local/lib/python3.7/site-packages/airflow/hooks/dbapi.py", line 181, in run
    with closing(self.get_conn()) as conn:
  File "/home/airflow/.local/lib/python3.7/site-packages/airflow/providers/postgres/hooks/postgres.py", line 86, in get_conn
    conn = deepcopy(self.connection or self.get_connection(conn_id))
  File "/home/airflow/.local/lib/python3.7/site-packages/airflow/hooks/base.py", line 67, in get_connection
    conn = Connection.get_connection_from_secrets(conn_id)
  File "/home/airflow/.local/lib/python3.7/site-packages/airflow/models/connection.py", line 430, in get_connection_from_secrets
    raise AirflowNotFoundException(f"The conn_id `{conn_id}` isn't defined")
airflow.exceptions.AirflowNotFoundException: The conn_id `postgres_default` isn't defined
[2022-12-12 12:30:40,046] {taskinstance.py:1400} INFO - Marking task as FAILED. dag_id=prepare_data, task_id=create_table, execution_date=20221128T165800, start_date=20221212T123030, end_date=20221212T123040
[2022-12-12 12:30:40,499] {standard_task_runner.py:97} ERROR - Failed to execute job 26 for task create_table (The conn_id `postgres_default` isn't defined; 310)
[2022-12-12 12:30:40,567] {local_task_job.py:156} INFO - Task exited with return code 1
[2022-12-12 12:30:41,263] {local_task_job.py:273} INFO - 0 downstream tasks scheduled from follow-on schedule check
[2022-12-12 15:14:42,758] {taskinstance.py:1159} INFO - Dependencies all met for <TaskInstance: prepare_data.create_table scheduled__2022-11-28T16:58:00+00:00 [queued]>
[2022-12-12 15:14:43,338] {taskinstance.py:1159} INFO - Dependencies all met for <TaskInstance: prepare_data.create_table scheduled__2022-11-28T16:58:00+00:00 [queued]>
[2022-12-12 15:14:43,358] {taskinstance.py:1356} INFO - 
--------------------------------------------------------------------------------
[2022-12-12 15:14:43,372] {taskinstance.py:1357} INFO - Starting attempt 1 of 1
[2022-12-12 15:14:43,438] {taskinstance.py:1358} INFO - 
--------------------------------------------------------------------------------
[2022-12-12 15:14:44,408] {taskinstance.py:1377} INFO - Executing <Task(PostgresOperator): create_table> on 2022-11-28 16:58:00+00:00
[2022-12-12 15:14:44,513] {standard_task_runner.py:52} INFO - Started process 345 to run task
[2022-12-12 15:14:44,813] {standard_task_runner.py:79} INFO - Running: ['airflow', 'tasks', 'run', 'prepare_data', 'create_table', 'scheduled__2022-11-28T16:58:00+00:00', '--job-id', '26', '--raw', '--subdir', 'DAGS_FOLDER/prepare_data.py', '--cfg-path', '/tmp/tmpf65vc64u', '--error-file', '/tmp/tmpiy1pudoj']
[2022-12-12 15:14:45,069] {standard_task_runner.py:80} INFO - Job 26: Subtask create_table
[2022-12-12 15:14:53,345] {task_command.py:369} INFO - Running <TaskInstance: prepare_data.create_table scheduled__2022-11-28T16:58:00+00:00 [running]> on host d4eb34144d92
[2022-12-12 15:15:10,409] {taskinstance.py:1571} INFO - Exporting the following env vars:
AIRFLOW_CTX_DAG_OWNER=airflow
AIRFLOW_CTX_DAG_ID=prepare_data
AIRFLOW_CTX_TASK_ID=create_table
AIRFLOW_CTX_EXECUTION_DATE=2022-11-28T16:58:00+00:00
AIRFLOW_CTX_TRY_NUMBER=1
AIRFLOW_CTX_DAG_RUN_ID=scheduled__2022-11-28T16:58:00+00:00
[2022-12-12 15:15:14,950] {taskinstance.py:1889} ERROR - Task failed with exception
Traceback (most recent call last):
  File "/home/airflow/.local/lib/python3.7/site-packages/airflow/providers/postgres/operators/postgres.py", line 92, in execute
    self.hook.run(self.sql, self.autocommit, parameters=self.parameters)
  File "/home/airflow/.local/lib/python3.7/site-packages/airflow/hooks/dbapi.py", line 181, in run
    with closing(self.get_conn()) as conn:
  File "/home/airflow/.local/lib/python3.7/site-packages/airflow/providers/postgres/hooks/postgres.py", line 86, in get_conn
    conn = deepcopy(self.connection or self.get_connection(conn_id))
  File "/home/airflow/.local/lib/python3.7/site-packages/airflow/hooks/base.py", line 67, in get_connection
    conn = Connection.get_connection_from_secrets(conn_id)
  File "/home/airflow/.local/lib/python3.7/site-packages/airflow/models/connection.py", line 430, in get_connection_from_secrets
    raise AirflowNotFoundException(f"The conn_id `{conn_id}` isn't defined")
airflow.exceptions.AirflowNotFoundException: The conn_id `postgres_default` isn't defined
[2022-12-12 15:15:16,486] {taskinstance.py:1400} INFO - Marking task as FAILED. dag_id=prepare_data, task_id=create_table, execution_date=20221128T165800, start_date=20221212T151442, end_date=20221212T151516
[2022-12-12 15:15:18,421] {standard_task_runner.py:97} ERROR - Failed to execute job 26 for task create_table (The conn_id `postgres_default` isn't defined; 345)
[2022-12-12 15:15:18,835] {local_task_job.py:156} INFO - Task exited with return code 1
[2022-12-12 15:15:22,196] {local_task_job.py:273} INFO - 0 downstream tasks scheduled from follow-on schedule check
