[2022-12-03 15:12:35,606] {taskinstance.py:1159} INFO - Dependencies all met for <TaskInstance: prepare_data.transfer_data scheduled__2022-11-28T19:57:00+00:00 [queued]>
[2022-12-03 15:12:36,215] {taskinstance.py:1159} INFO - Dependencies all met for <TaskInstance: prepare_data.transfer_data scheduled__2022-11-28T19:57:00+00:00 [queued]>
[2022-12-03 15:12:36,216] {taskinstance.py:1356} INFO - 
--------------------------------------------------------------------------------
[2022-12-03 15:12:36,216] {taskinstance.py:1357} INFO - Starting attempt 1 of 1
[2022-12-03 15:12:36,216] {taskinstance.py:1358} INFO - 
--------------------------------------------------------------------------------
[2022-12-03 15:12:36,943] {taskinstance.py:1377} INFO - Executing <Task(PythonOperator): transfer_data> on 2022-11-28 19:57:00+00:00
[2022-12-03 15:12:37,116] {standard_task_runner.py:52} INFO - Started process 1345 to run task
[2022-12-03 15:12:37,282] {standard_task_runner.py:79} INFO - Running: ['airflow', 'tasks', 'run', 'prepare_data', 'transfer_data', 'scheduled__2022-11-28T19:57:00+00:00', '--job-id', '431', '--raw', '--subdir', 'DAGS_FOLDER/prepare_data.py', '--cfg-path', '/tmp/tmp6vy_9jy3', '--error-file', '/tmp/tmp4zm1f8il']
[2022-12-03 15:12:37,345] {standard_task_runner.py:80} INFO - Job 431: Subtask transfer_data
[2022-12-03 15:12:39,550] {task_command.py:369} INFO - Running <TaskInstance: prepare_data.transfer_data scheduled__2022-11-28T19:57:00+00:00 [running]> on host b41792e8e843
[2022-12-03 15:12:42,332] {taskinstance.py:1571} INFO - Exporting the following env vars:
AIRFLOW_CTX_DAG_OWNER=airflow
AIRFLOW_CTX_DAG_ID=prepare_data
AIRFLOW_CTX_TASK_ID=transfer_data
AIRFLOW_CTX_EXECUTION_DATE=2022-11-28T19:57:00+00:00
AIRFLOW_CTX_TRY_NUMBER=1
AIRFLOW_CTX_DAG_RUN_ID=scheduled__2022-11-28T19:57:00+00:00
[2022-12-03 15:12:42,769] {base.py:68} INFO - Using connection ID 'postgres_default' for task execution.
[2022-12-03 15:12:43,465] {python.py:173} INFO - Done. Returned value was: None
[2022-12-03 15:12:44,754] {local_task_job.py:84} ERROR - Received SIGTERM. Terminating subprocesses
[2022-12-03 15:12:44,945] {taskinstance.py:1400} INFO - Marking task as SUCCESS. dag_id=prepare_data, task_id=transfer_data, execution_date=20221128T195700, start_date=20221203T151235, end_date=20221203T151244
[2022-12-03 15:12:45,350] {process_utils.py:129} INFO - Sending Signals.SIGTERM to group 1345. PIDs of all processes in the group: [1345]
[2022-12-03 15:12:45,604] {process_utils.py:80} INFO - Sending the signal Signals.SIGTERM to group 1345
[2022-12-03 15:12:45,847] {taskinstance.py:1541} ERROR - Received SIGTERM. Terminating subprocesses.
[2022-12-03 15:12:46,378] {standard_task_runner.py:97} ERROR - Failed to execute job 431 for task transfer_data ((psycopg2.InterfaceError) connection already closed
(Background on this error at: http://sqlalche.me/e/14/rvf5); 1345)
[2022-12-03 15:12:50,981] {process_utils.py:75} INFO - Process psutil.Process(pid=1345, status='terminated', exitcode=1, started='15:12:36') (1345) terminated with exit code 1
[2022-12-03 15:12:50,983] {local_task_job.py:156} INFO - Task exited with return code 143
