[2022-12-03 14:46:02,995] {taskinstance.py:1159} INFO - Dependencies all met for <TaskInstance: prepare_data.create_table scheduled__2022-11-28T17:18:00+00:00 [queued]>
[2022-12-03 14:46:03,241] {taskinstance.py:1159} INFO - Dependencies all met for <TaskInstance: prepare_data.create_table scheduled__2022-11-28T17:18:00+00:00 [queued]>
[2022-12-03 14:46:03,242] {taskinstance.py:1356} INFO - 
--------------------------------------------------------------------------------
[2022-12-03 14:46:03,242] {taskinstance.py:1357} INFO - Starting attempt 1 of 1
[2022-12-03 14:46:03,242] {taskinstance.py:1358} INFO - 
--------------------------------------------------------------------------------
[2022-12-03 14:46:03,647] {taskinstance.py:1377} INFO - Executing <Task(PostgresOperator): create_table> on 2022-11-28 17:18:00+00:00
[2022-12-03 14:46:03,680] {standard_task_runner.py:52} INFO - Started process 365 to run task
[2022-12-03 14:46:03,778] {standard_task_runner.py:79} INFO - Running: ['airflow', 'tasks', 'run', 'prepare_data', 'create_table', 'scheduled__2022-11-28T17:18:00+00:00', '--job-id', '46', '--raw', '--subdir', 'DAGS_FOLDER/prepare_data.py', '--cfg-path', '/tmp/tmprfxe0ren', '--error-file', '/tmp/tmpxbe7h0ez']
[2022-12-03 14:46:03,813] {standard_task_runner.py:80} INFO - Job 46: Subtask create_table
[2022-12-03 14:46:05,312] {task_command.py:369} INFO - Running <TaskInstance: prepare_data.create_table scheduled__2022-11-28T17:18:00+00:00 [running]> on host b41792e8e843
[2022-12-03 14:46:07,244] {taskinstance.py:1571} INFO - Exporting the following env vars:
AIRFLOW_CTX_DAG_OWNER=airflow
AIRFLOW_CTX_DAG_ID=prepare_data
AIRFLOW_CTX_TASK_ID=create_table
AIRFLOW_CTX_EXECUTION_DATE=2022-11-28T17:18:00+00:00
AIRFLOW_CTX_TRY_NUMBER=1
AIRFLOW_CTX_DAG_RUN_ID=scheduled__2022-11-28T17:18:00+00:00
[2022-12-03 14:46:07,576] {taskinstance.py:1889} ERROR - Task failed with exception
Traceback (most recent call last):
  File "/home/airflow/.local/lib/python3.7/site-packages/airflow/providers/postgres/operators/postgres.py", line 92, in execute
    self.hook.run(self.sql, self.autocommit, parameters=self.parameters)
  File "/home/airflow/.local/lib/python3.7/site-packages/airflow/hooks/dbapi.py", line 181, in run
    with closing(self.get_conn()) as conn:
  File "/home/airflow/.local/lib/python3.7/site-packages/airflow/providers/postgres/hooks/postgres.py", line 86, in get_conn
    conn = deepcopy(self.connection or self.get_connection(conn_id))
  File "/home/airflow/.local/lib/python3.7/site-packages/airflow/hooks/base.py", line 67, in get_connection
    conn = Connection.get_connection_from_secrets(conn_id)
  File "/home/airflow/.local/lib/python3.7/site-packages/airflow/models/connection.py", line 430, in get_connection_from_secrets
    raise AirflowNotFoundException(f"The conn_id `{conn_id}` isn't defined")
airflow.exceptions.AirflowNotFoundException: The conn_id `postgres_default` isn't defined
[2022-12-03 14:46:07,667] {taskinstance.py:1400} INFO - Marking task as FAILED. dag_id=prepare_data, task_id=create_table, execution_date=20221128T171800, start_date=20221203T144602, end_date=20221203T144607
[2022-12-03 14:46:07,977] {standard_task_runner.py:97} ERROR - Failed to execute job 46 for task create_table (The conn_id `postgres_default` isn't defined; 365)
[2022-12-03 14:46:08,126] {local_task_job.py:156} INFO - Task exited with return code 1
[2022-12-03 14:46:08,985] {local_task_job.py:273} INFO - 0 downstream tasks scheduled from follow-on schedule check
[2022-12-12 12:31:29,121] {taskinstance.py:1159} INFO - Dependencies all met for <TaskInstance: prepare_data.create_table scheduled__2022-11-28T17:18:00+00:00 [queued]>
[2022-12-12 12:31:29,412] {taskinstance.py:1159} INFO - Dependencies all met for <TaskInstance: prepare_data.create_table scheduled__2022-11-28T17:18:00+00:00 [queued]>
[2022-12-12 12:31:29,412] {taskinstance.py:1356} INFO - 
--------------------------------------------------------------------------------
[2022-12-12 12:31:29,412] {taskinstance.py:1357} INFO - Starting attempt 1 of 1
[2022-12-12 12:31:29,412] {taskinstance.py:1358} INFO - 
--------------------------------------------------------------------------------
[2022-12-12 12:31:29,770] {taskinstance.py:1377} INFO - Executing <Task(PostgresOperator): create_table> on 2022-11-28 17:18:00+00:00
[2022-12-12 12:31:29,785] {standard_task_runner.py:52} INFO - Started process 359 to run task
[2022-12-12 12:31:29,860] {standard_task_runner.py:79} INFO - Running: ['airflow', 'tasks', 'run', 'prepare_data', 'create_table', 'scheduled__2022-11-28T17:18:00+00:00', '--job-id', '46', '--raw', '--subdir', 'DAGS_FOLDER/prepare_data.py', '--cfg-path', '/tmp/tmp3hdvrroa', '--error-file', '/tmp/tmpjnjdmfnu']
[2022-12-12 12:31:29,875] {standard_task_runner.py:80} INFO - Job 46: Subtask create_table
[2022-12-12 12:31:30,652] {task_command.py:369} INFO - Running <TaskInstance: prepare_data.create_table scheduled__2022-11-28T17:18:00+00:00 [running]> on host b778137d8ea6
[2022-12-12 12:31:32,031] {taskinstance.py:1571} INFO - Exporting the following env vars:
AIRFLOW_CTX_DAG_OWNER=airflow
AIRFLOW_CTX_DAG_ID=prepare_data
AIRFLOW_CTX_TASK_ID=create_table
AIRFLOW_CTX_EXECUTION_DATE=2022-11-28T17:18:00+00:00
AIRFLOW_CTX_TRY_NUMBER=1
AIRFLOW_CTX_DAG_RUN_ID=scheduled__2022-11-28T17:18:00+00:00
[2022-12-12 12:31:32,374] {taskinstance.py:1889} ERROR - Task failed with exception
Traceback (most recent call last):
  File "/home/airflow/.local/lib/python3.7/site-packages/airflow/providers/postgres/operators/postgres.py", line 92, in execute
    self.hook.run(self.sql, self.autocommit, parameters=self.parameters)
  File "/home/airflow/.local/lib/python3.7/site-packages/airflow/hooks/dbapi.py", line 181, in run
    with closing(self.get_conn()) as conn:
  File "/home/airflow/.local/lib/python3.7/site-packages/airflow/providers/postgres/hooks/postgres.py", line 86, in get_conn
    conn = deepcopy(self.connection or self.get_connection(conn_id))
  File "/home/airflow/.local/lib/python3.7/site-packages/airflow/hooks/base.py", line 67, in get_connection
    conn = Connection.get_connection_from_secrets(conn_id)
  File "/home/airflow/.local/lib/python3.7/site-packages/airflow/models/connection.py", line 430, in get_connection_from_secrets
    raise AirflowNotFoundException(f"The conn_id `{conn_id}` isn't defined")
airflow.exceptions.AirflowNotFoundException: The conn_id `postgres_default` isn't defined
[2022-12-12 12:31:32,432] {taskinstance.py:1400} INFO - Marking task as FAILED. dag_id=prepare_data, task_id=create_table, execution_date=20221128T171800, start_date=20221212T123129, end_date=20221212T123132
[2022-12-12 12:31:32,574] {standard_task_runner.py:97} ERROR - Failed to execute job 46 for task create_table (The conn_id `postgres_default` isn't defined; 359)
[2022-12-12 12:31:32,619] {local_task_job.py:156} INFO - Task exited with return code 1
[2022-12-12 12:31:33,270] {local_task_job.py:273} INFO - 0 downstream tasks scheduled from follow-on schedule check
[2022-12-12 15:18:23,926] {taskinstance.py:1159} INFO - Dependencies all met for <TaskInstance: prepare_data.create_table scheduled__2022-11-28T17:18:00+00:00 [queued]>
[2022-12-12 15:18:24,153] {taskinstance.py:1159} INFO - Dependencies all met for <TaskInstance: prepare_data.create_table scheduled__2022-11-28T17:18:00+00:00 [queued]>
[2022-12-12 15:18:24,154] {taskinstance.py:1356} INFO - 
--------------------------------------------------------------------------------
[2022-12-12 15:18:24,154] {taskinstance.py:1357} INFO - Starting attempt 1 of 1
[2022-12-12 15:18:24,155] {taskinstance.py:1358} INFO - 
--------------------------------------------------------------------------------
[2022-12-12 15:18:24,472] {taskinstance.py:1377} INFO - Executing <Task(PostgresOperator): create_table> on 2022-11-28 17:18:00+00:00
[2022-12-12 15:18:24,519] {standard_task_runner.py:52} INFO - Started process 408 to run task
[2022-12-12 15:18:24,600] {standard_task_runner.py:79} INFO - Running: ['airflow', 'tasks', 'run', 'prepare_data', 'create_table', 'scheduled__2022-11-28T17:18:00+00:00', '--job-id', '46', '--raw', '--subdir', 'DAGS_FOLDER/prepare_data.py', '--cfg-path', '/tmp/tmpiwe28pqw', '--error-file', '/tmp/tmp8asx7fs7']
[2022-12-12 15:18:24,628] {standard_task_runner.py:80} INFO - Job 46: Subtask create_table
[2022-12-12 15:18:26,632] {task_command.py:369} INFO - Running <TaskInstance: prepare_data.create_table scheduled__2022-11-28T17:18:00+00:00 [running]> on host d4eb34144d92
[2022-12-12 15:18:29,271] {taskinstance.py:1571} INFO - Exporting the following env vars:
AIRFLOW_CTX_DAG_OWNER=airflow
AIRFLOW_CTX_DAG_ID=prepare_data
AIRFLOW_CTX_TASK_ID=create_table
AIRFLOW_CTX_EXECUTION_DATE=2022-11-28T17:18:00+00:00
AIRFLOW_CTX_TRY_NUMBER=1
AIRFLOW_CTX_DAG_RUN_ID=scheduled__2022-11-28T17:18:00+00:00
[2022-12-12 15:18:30,581] {taskinstance.py:1889} ERROR - Task failed with exception
Traceback (most recent call last):
  File "/home/airflow/.local/lib/python3.7/site-packages/airflow/providers/postgres/operators/postgres.py", line 92, in execute
    self.hook.run(self.sql, self.autocommit, parameters=self.parameters)
  File "/home/airflow/.local/lib/python3.7/site-packages/airflow/hooks/dbapi.py", line 181, in run
    with closing(self.get_conn()) as conn:
  File "/home/airflow/.local/lib/python3.7/site-packages/airflow/providers/postgres/hooks/postgres.py", line 86, in get_conn
    conn = deepcopy(self.connection or self.get_connection(conn_id))
  File "/home/airflow/.local/lib/python3.7/site-packages/airflow/hooks/base.py", line 67, in get_connection
    conn = Connection.get_connection_from_secrets(conn_id)
  File "/home/airflow/.local/lib/python3.7/site-packages/airflow/models/connection.py", line 430, in get_connection_from_secrets
    raise AirflowNotFoundException(f"The conn_id `{conn_id}` isn't defined")
airflow.exceptions.AirflowNotFoundException: The conn_id `postgres_default` isn't defined
[2022-12-12 15:18:30,820] {taskinstance.py:1400} INFO - Marking task as FAILED. dag_id=prepare_data, task_id=create_table, execution_date=20221128T171800, start_date=20221212T151823, end_date=20221212T151830
[2022-12-12 15:18:31,528] {standard_task_runner.py:97} ERROR - Failed to execute job 46 for task create_table (The conn_id `postgres_default` isn't defined; 408)
[2022-12-12 15:18:32,025] {local_task_job.py:156} INFO - Task exited with return code 1
[2022-12-12 15:18:33,673] {local_task_job.py:273} INFO - 0 downstream tasks scheduled from follow-on schedule check
