[2022-12-03 14:47:41,768] {taskinstance.py:1159} INFO - Dependencies all met for <TaskInstance: prepare_data.create_table scheduled__2022-11-28T17:52:00+00:00 [queued]>
[2022-12-03 14:47:42,064] {taskinstance.py:1159} INFO - Dependencies all met for <TaskInstance: prepare_data.create_table scheduled__2022-11-28T17:52:00+00:00 [queued]>
[2022-12-03 14:47:42,065] {taskinstance.py:1356} INFO - 
--------------------------------------------------------------------------------
[2022-12-03 14:47:42,086] {taskinstance.py:1357} INFO - Starting attempt 1 of 1
[2022-12-03 14:47:42,086] {taskinstance.py:1358} INFO - 
--------------------------------------------------------------------------------
[2022-12-03 14:47:42,630] {taskinstance.py:1377} INFO - Executing <Task(PostgresOperator): create_table> on 2022-11-28 17:52:00+00:00
[2022-12-03 14:47:42,793] {standard_task_runner.py:52} INFO - Started process 448 to run task
[2022-12-03 14:47:43,117] {standard_task_runner.py:79} INFO - Running: ['airflow', 'tasks', 'run', 'prepare_data', 'create_table', 'scheduled__2022-11-28T17:52:00+00:00', '--job-id', '80', '--raw', '--subdir', 'DAGS_FOLDER/prepare_data.py', '--cfg-path', '/tmp/tmpbhm04a38', '--error-file', '/tmp/tmpy3462jig']
[2022-12-03 14:47:43,120] {standard_task_runner.py:80} INFO - Job 80: Subtask create_table
[2022-12-03 14:47:44,595] {task_command.py:369} INFO - Running <TaskInstance: prepare_data.create_table scheduled__2022-11-28T17:52:00+00:00 [running]> on host b41792e8e843
[2022-12-03 14:47:46,313] {taskinstance.py:1571} INFO - Exporting the following env vars:
AIRFLOW_CTX_DAG_OWNER=airflow
AIRFLOW_CTX_DAG_ID=prepare_data
AIRFLOW_CTX_TASK_ID=create_table
AIRFLOW_CTX_EXECUTION_DATE=2022-11-28T17:52:00+00:00
AIRFLOW_CTX_TRY_NUMBER=1
AIRFLOW_CTX_DAG_RUN_ID=scheduled__2022-11-28T17:52:00+00:00
[2022-12-03 14:47:48,613] {taskinstance.py:1889} ERROR - Task failed with exception
Traceback (most recent call last):
  File "/home/airflow/.local/lib/python3.7/site-packages/airflow/providers/postgres/operators/postgres.py", line 92, in execute
    self.hook.run(self.sql, self.autocommit, parameters=self.parameters)
  File "/home/airflow/.local/lib/python3.7/site-packages/airflow/hooks/dbapi.py", line 181, in run
    with closing(self.get_conn()) as conn:
  File "/home/airflow/.local/lib/python3.7/site-packages/airflow/providers/postgres/hooks/postgres.py", line 86, in get_conn
    conn = deepcopy(self.connection or self.get_connection(conn_id))
  File "/home/airflow/.local/lib/python3.7/site-packages/airflow/hooks/base.py", line 67, in get_connection
    conn = Connection.get_connection_from_secrets(conn_id)
  File "/home/airflow/.local/lib/python3.7/site-packages/airflow/models/connection.py", line 430, in get_connection_from_secrets
    raise AirflowNotFoundException(f"The conn_id `{conn_id}` isn't defined")
airflow.exceptions.AirflowNotFoundException: The conn_id `postgres_default` isn't defined
[2022-12-03 14:47:48,708] {taskinstance.py:1400} INFO - Marking task as FAILED. dag_id=prepare_data, task_id=create_table, execution_date=20221128T175200, start_date=20221203T144741, end_date=20221203T144748
[2022-12-03 14:47:49,156] {standard_task_runner.py:97} ERROR - Failed to execute job 80 for task create_table (The conn_id `postgres_default` isn't defined; 448)
[2022-12-03 14:47:49,329] {local_task_job.py:156} INFO - Task exited with return code 1
[2022-12-03 14:47:50,289] {local_task_job.py:273} INFO - 0 downstream tasks scheduled from follow-on schedule check
[2022-12-12 12:33:00,505] {taskinstance.py:1159} INFO - Dependencies all met for <TaskInstance: prepare_data.create_table scheduled__2022-11-28T17:52:00+00:00 [queued]>
[2022-12-12 12:33:00,647] {taskinstance.py:1159} INFO - Dependencies all met for <TaskInstance: prepare_data.create_table scheduled__2022-11-28T17:52:00+00:00 [queued]>
[2022-12-12 12:33:00,647] {taskinstance.py:1356} INFO - 
--------------------------------------------------------------------------------
[2022-12-12 12:33:00,647] {taskinstance.py:1357} INFO - Starting attempt 1 of 1
[2022-12-12 12:33:00,647] {taskinstance.py:1358} INFO - 
--------------------------------------------------------------------------------
[2022-12-12 12:33:00,925] {taskinstance.py:1377} INFO - Executing <Task(PostgresOperator): create_table> on 2022-11-28 17:52:00+00:00
[2022-12-12 12:33:00,983] {standard_task_runner.py:52} INFO - Started process 441 to run task
[2022-12-12 12:33:01,006] {standard_task_runner.py:79} INFO - Running: ['airflow', 'tasks', 'run', 'prepare_data', 'create_table', 'scheduled__2022-11-28T17:52:00+00:00', '--job-id', '80', '--raw', '--subdir', 'DAGS_FOLDER/prepare_data.py', '--cfg-path', '/tmp/tmp9pij9jx6', '--error-file', '/tmp/tmpcoqqwgo2']
[2022-12-12 12:33:01,050] {standard_task_runner.py:80} INFO - Job 80: Subtask create_table
[2022-12-12 12:33:01,867] {task_command.py:369} INFO - Running <TaskInstance: prepare_data.create_table scheduled__2022-11-28T17:52:00+00:00 [running]> on host b778137d8ea6
[2022-12-12 12:33:03,055] {taskinstance.py:1571} INFO - Exporting the following env vars:
AIRFLOW_CTX_DAG_OWNER=airflow
AIRFLOW_CTX_DAG_ID=prepare_data
AIRFLOW_CTX_TASK_ID=create_table
AIRFLOW_CTX_EXECUTION_DATE=2022-11-28T17:52:00+00:00
AIRFLOW_CTX_TRY_NUMBER=1
AIRFLOW_CTX_DAG_RUN_ID=scheduled__2022-11-28T17:52:00+00:00
[2022-12-12 12:33:04,101] {taskinstance.py:1889} ERROR - Task failed with exception
Traceback (most recent call last):
  File "/home/airflow/.local/lib/python3.7/site-packages/airflow/providers/postgres/operators/postgres.py", line 92, in execute
    self.hook.run(self.sql, self.autocommit, parameters=self.parameters)
  File "/home/airflow/.local/lib/python3.7/site-packages/airflow/hooks/dbapi.py", line 181, in run
    with closing(self.get_conn()) as conn:
  File "/home/airflow/.local/lib/python3.7/site-packages/airflow/providers/postgres/hooks/postgres.py", line 86, in get_conn
    conn = deepcopy(self.connection or self.get_connection(conn_id))
  File "/home/airflow/.local/lib/python3.7/site-packages/airflow/hooks/base.py", line 67, in get_connection
    conn = Connection.get_connection_from_secrets(conn_id)
  File "/home/airflow/.local/lib/python3.7/site-packages/airflow/models/connection.py", line 430, in get_connection_from_secrets
    raise AirflowNotFoundException(f"The conn_id `{conn_id}` isn't defined")
airflow.exceptions.AirflowNotFoundException: The conn_id `postgres_default` isn't defined
[2022-12-12 12:33:04,199] {taskinstance.py:1400} INFO - Marking task as FAILED. dag_id=prepare_data, task_id=create_table, execution_date=20221128T175200, start_date=20221212T123300, end_date=20221212T123304
[2022-12-12 12:33:04,393] {standard_task_runner.py:97} ERROR - Failed to execute job 80 for task create_table (The conn_id `postgres_default` isn't defined; 441)
[2022-12-12 12:33:04,571] {local_task_job.py:156} INFO - Task exited with return code 1
[2022-12-12 12:33:05,365] {local_task_job.py:273} INFO - 0 downstream tasks scheduled from follow-on schedule check
